Workbook
Name DataExported: Inflación!$B$1:$K$30
Name DataExported: TPM!$B$1:$W$371

Sheet Datos para el modelo
B1: Fecha | C1: PD 90+ | D1: TPM | E1: FX | F1: INF_YOY
B2: =+'PD (Morosidad)'!C2 -> 45292 | C2: =+'PD (Morosidad)'!E2 -> 0.010165377 | D2: =+TPM!U36 -> 5.75 | E2: =+GETPIVOTDATA("Tipo cambio venta",'Tipo de cambio'!$F$5,"Months (Fecha)",1,"Years (Fecha)",2024) -> 521.51581 | F2: =+Inflación!E6 -> -1.868634
B3: =+'PD (Morosidad)'!C3 -> 45323 | C3: =+'PD (Morosidad)'!E3 -> 0.010738193 | D3: =+TPM!U65 -> 5.75 | E3: =+GETPIVOTDATA("Tipo cambio venta",'Tipo de cambio'!$F$5,"Months (Fecha)",2,"Years (Fecha)",2024) -> 519.45862 | F3: =+Inflación!E7 -> -1.131406
B4: =+'PD (Morosidad)'!C4 -> 45352 | C4: =+'PD (Morosidad)'!E4 -> 0.011747474 | D4: =+TPM!U96 -> 5.25 | E4: =+GETPIVOTDATA("Tipo cambio venta",'Tipo de cambio'!$F$5,"Months (Fecha)",3,"Years (Fecha)",2024) -> 510.02129 | F4: =+Inflación!E8 -> -1.1863148
B5: =+'PD (Morosidad)'!C5 -> 45383 | C5: =+'PD (Morosidad)'!E5 -> 0.012473501 | D5: =+TPM!U126 -> 4.75 | E5: =+GETPIVOTDATA("Tipo cambio venta",'Tipo de cambio'!$F$5,"Months (Fecha)",4,"Years (Fecha)",2024) -> 504.981 | F5: =+Inflación!E9 -> -0.52081297
B6: =+'PD (Morosidad)'!C6 -> 45413 | C6: =+'PD (Morosidad)'!E6 -> 0.013492357 | D6: =+TPM!U157 -> 4.75 | E6: =+GETPIVOTDATA("Tipo cambio venta",'Tipo de cambio'!$F$5,"Months (Fecha)",5,"Years (Fecha)",2024) -> 515.43742 | F6: =+Inflación!E10 -> -0.33476582
B7: =+'PD (Morosidad)'!C7 -> 45444 | C7: =+'PD (Morosidad)'!E7 -> 0.010710684 | D7: =+TPM!U187 -> 4.75 | E7: =+GETPIVOTDATA("Tipo cambio venta",'Tipo de cambio'!$F$5,"Months (Fecha)",6,"Years (Fecha)",2024) -> 528.993 | F7: =+Inflación!E11 -> -0.03375699
B8: =+'PD (Morosidad)'!C8 -> 45474 | C8: =+'PD (Morosidad)'!E8 -> 0.010953393 | D8: =+TPM!U218 -> 4.75 | E8: =+GETPIVOTDATA("Tipo cambio venta",'Tipo de cambio'!$F$5,"Months (Fecha)",7,"Years (Fecha)",2024) -> 529.24774 | F8: =+Inflación!E12 -> 0.03187455
B9: =+'PD (Morosidad)'!C9 -> 45505 | C9: =+'PD (Morosidad)'!E9 -> 0.011597034 | D9: =+TPM!U249 -> 4.75 | E9: =+GETPIVOTDATA("Tipo cambio venta",'Tipo de cambio'!$F$5,"Months (Fecha)",8,"Years (Fecha)",2024) -> 525.70355 | F9: =+Inflación!E13 -> 0.31250425
B10: =+'PD (Morosidad)'!C10 -> 45536 | C10: =+'PD (Morosidad)'!E10 -> 0.012029055 | D10: =+TPM!U279 -> 4.25 | E10: =+GETPIVOTDATA("Tipo cambio venta",'Tipo de cambio'!$F$5,"Months (Fecha)",9,"Years (Fecha)",2024) -> 522.019 | F10: =+Inflación!E14 -> -0.13585182
B11: =+'PD (Morosidad)'!C11 -> 45566 | C11: =+'PD (Morosidad)'!E11 -> 0.011916556 | D11: =+TPM!U310 -> 4 | E11: =+GETPIVOTDATA("Tipo cambio venta",'Tipo de cambio'!$F$5,"Months (Fecha)",10,"Years (Fecha)",2024) -> 518.64903 | F11: =+Inflación!E15 -> -0.7863946
B12: =+'PD (Morosidad)'!C12 -> 45597 | C12: =+'PD (Morosidad)'!E12 -> 0.012037239 | D12: =+TPM!U340 -> 4 | E12: =+GETPIVOTDATA("Tipo cambio venta",'Tipo de cambio'!$F$5,"Months (Fecha)",11,"Years (Fecha)",2024) -> 513.608 | F12: =+Inflación!E16 -> -0.09182255
B13: =+'PD (Morosidad)'!C13 -> 45627 | C13: =+'PD (Morosidad)'!E13 -> 0.01191713 | D13: =+TPM!U371 -> 4 | E13: =+GETPIVOTDATA("Tipo cambio venta",'Tipo de cambio'!$F$5,"Months (Fecha)",12,"Years (Fecha)",2024) -> 509.1371 | F13: =+Inflación!E17 -> 0.8417193
B14: =+'PD (Morosidad)'!C14 -> 45658 | C14: =+'PD (Morosidad)'!E14 -> 0.011882143 | D14: =+TPM!V36 -> 4 | E14: =+GETPIVOTDATA("Tipo cambio venta",'Tipo de cambio'!$F$5,"Months (Fecha)",1,"Years (Fecha)",2025) -> 508.67452 | F14: =+Inflación!E18 -> 1.150493
B15: =+'PD (Morosidad)'!C15 -> 45689 | C15: =+'PD (Morosidad)'!E15 -> 0.01148865 | D15: =+TPM!V65 -> 0 | E15: =+GETPIVOTDATA("Tipo cambio venta",'Tipo de cambio'!$F$5,"Months (Fecha)",2,"Years (Fecha)",2025) -> 509.92357 | F15: =+Inflación!E19 -> 1.2465414
B16: =+'PD (Morosidad)'!C16 -> 45717 | C16: =+'PD (Morosidad)'!E16 -> 0.011103786 | D16: =+TPM!V96 -> 4 | E16: =+GETPIVOTDATA("Tipo cambio venta",'Tipo de cambio'!$F$5,"Months (Fecha)",3,"Years (Fecha)",2025) -> 504.40355 | F16: =+Inflación!E20 -> 1.2125843
B17: =+'PD (Morosidad)'!C17 -> 45748 | C17: =+'PD (Morosidad)'!E17 -> 0.012641225 | D17: =+TPM!V126 -> 4 | E17: =+GETPIVOTDATA("Tipo cambio venta",'Tipo de cambio'!$F$5,"Months (Fecha)",4,"Years (Fecha)",2025) -> 508.35533 | F17: =+Inflación!E21 -> 0.37188968
B18: =+'PD (Morosidad)'!C18 -> 45778 | C18: =+'PD (Morosidad)'!E18 -> 0.012979844 | D18: =+TPM!V157 -> 4 | E18: =+GETPIVOTDATA("Tipo cambio venta",'Tipo de cambio'!$F$5,"Months (Fecha)",5,"Years (Fecha)",2025) -> 509.32806 | F18: =+Inflación!E22 -> -0.11552014
B19: =+'PD (Morosidad)'!C19 -> 45809 | C19: =+'PD (Morosidad)'!E19 -> 0.01190252 | D19: =+TPM!V187 -> 4 | E19: =+GETPIVOTDATA("Tipo cambio venta",'Tipo de cambio'!$F$5,"Months (Fecha)",6,"Years (Fecha)",2025) -> 508.63633 | F19: =+Inflación!E23 -> -0.21516412
B20: =+'PD (Morosidad)'!C20 -> 45839 | C20: =+'PD (Morosidad)'!E20 -> 0.012059827 | D20: =+TPM!V218 -> 3.75 | E20: =+GETPIVOTDATA("Tipo cambio venta",'Tipo de cambio'!$F$5,"Months (Fecha)",7,"Years (Fecha)",2025) -> 507.23484 | F20: =+Inflación!E24 -> -0.60816885
B21: =+'PD (Morosidad)'!C21 -> 45870 | C21: =+'PD (Morosidad)'!E21 -> 0.012067685 | D21: =+TPM!V249 -> 3.75 | E21: =+GETPIVOTDATA("Tipo cambio venta",'Tipo de cambio'!$F$5,"Months (Fecha)",8,"Years (Fecha)",2025) -> 507.73548 | F21: =+Inflación!E25 -> -0.93582989
B22: =+'PD (Morosidad)'!C22 -> 45901 | C22: =+'PD (Morosidad)'!E22 -> 0.010892421 | D22: =+TPM!V279 -> 3.5 | E22: =+GETPIVOTDATA("Tipo cambio venta",'Tipo de cambio'!$F$5,"Months (Fecha)",9,"Years (Fecha)",2025) -> 507.50667 | F22: =+Inflación!E26 -> -1.0032326
B23: =+'PD (Morosidad)'!C23 -> 45931 | C23: =+'PD (Morosidad)'!E23 -> 0.010747452 | D23: =+TPM!V310 -> 3.5 | E23: =+GETPIVOTDATA("Tipo cambio venta",'Tipo de cambio'!$F$5,"Months (Fecha)",10,"Years (Fecha)",2025) -> 506.00194 | F23: =+Inflación!E27 -> -0.37764121
B24: =+'PD (Morosidad)'!C24 -> 45962 | C24: =+'PD (Morosidad)'!E24 -> 0.01186597 | D24: =+TPM!V340 -> 3.5 | E24: =+GETPIVOTDATA("Tipo cambio venta",'Tipo de cambio'!$F$5,"Months (Fecha)",11,"Years (Fecha)",2025) -> 502.41 | F24: =+Inflación!E28 -> -0.37595225
B25: =+'PD (Morosidad)'!C25 -> 45992 | C25: =+'PD (Morosidad)'!E25 -> 0.012003634 | D25: =+TPM!V371 -> 3.25 | E25: =+GETPIVOTDATA("Tipo cambio venta",'Tipo de cambio'!$F$5,"Months (Fecha)",12,"Years (Fecha)",2025) -> 497.75968 | F25: =+Inflación!E29 -> -1.2267773
B26: =+'PD (Morosidad)'!C26 -> 46023 | C26: =+'PD (Morosidad)'!E26 -> 0.0099209687 | D26: =+TPM!W36 -> 3.25 | E26: =+GETPIVOTDATA("Tipo cambio venta",'Tipo de cambio'!$F$5,"Months (Fecha)",1,"Years (Fecha)",2026) -> 497.94419 | F26: =+Inflación!E30 -> -2.5307416

Sheet PD (Morosidad)
B1: Fecha | E1: PD 90+ | F1: Total | G1: 1 a 30 días | H1: 31 a 60 días | I1: 61 a 90 días | J1: 91 a 180 días | K1: Al día | L1: Cobro judicial | M1: Más de 180 días | O1: Total cartera | P1: Diferencia
B2: 2024-01 | C2: =DATE(LEFT(B2,4),RIGHT(B2,2),1) -> 45292 | D2: =ISNUMBER(C2) -> TRUE | E2: =+(J2+M2)/F2 -> 0.010165377 | F2: =SUM(G2:M2) -> 2.4101746e+13 | G2: 7.430879e+11 | H2: 3.6502981e+11 | I2: 1.8776588e+11 | J2: 1.2177425e+11 | K2: 2.2311059e+13 | L2: 2.4980041e+11 | M2: 1.232291e+11 | O2: 2.4101746e+13 | P2: =+F2-O2 -> 0
B3: 2024-02 | C3: =DATE(LEFT(B3,4),RIGHT(B3,2),1) -> 45323 | D3: =ISNUMBER(C3) -> TRUE | E3: =+(J3+M3)/F3 -> 0.010738193 | F3: =SUM(G3:M3) -> 2.4114389e+13 | G3: 8.7652054e+11 | H3: 3.5808516e+11 | I3: 1.638084e+11 | J3: 1.3072164e+11 | K3: 2.2210644e+13 | L3: 2.463861e+11 | M3: 1.2822331e+11 | O3: 2.4114389e+13 | P3: =+F3-O3 -> 0
B4: 2024-03 | C4: =DATE(LEFT(B4,4),RIGHT(B4,2),1) -> 45352 | D4: =ISNUMBER(C4) -> TRUE | E4: =+(J4+M4)/F4 -> 0.011747474 | F4: =SUM(G4:M4) -> 2.4051653e+13 | G4: 8.4605892e+11 | H4: 4.3960089e+11 | I4: 1.8701914e+11 | J4: 1.4944917e+11 | K4: 2.2053869e+13 | L4: 2.4255907e+11 | M4: 1.33097e+11 | O4: 2.4051653e+13 | P4: =+F4-O4 -> 0
B5: 2024-04 | C5: =DATE(LEFT(B5,4),RIGHT(B5,2),1) -> 45383 | D5: =ISNUMBER(C5) -> TRUE | E5: =+(J5+M5)/F5 -> 0.012473501 | F5: =SUM(G5:M5) -> 2.4234857e+13 | G5: 8.4427535e+11 | H5: 3.3908455e+11 | I5: 2.2345396e+11 | J5: 1.6330622e+11 | K5: 2.2280926e+13 | L5: 2.4482381e+11 | M5: 1.389873e+11 | O5: 2.4234857e+13 | P5: =+F5-O5 -> 0
B6: 2024-05 | C6: =DATE(LEFT(B6,4),RIGHT(B6,2),1) -> 45413 | D6: =ISNUMBER(C6) -> TRUE | E6: =+(J6+M6)/F6 -> 0.013492357 | F6: =SUM(G6:M6) -> 2.4661737e+13 | G6: 7.8029687e+11 | H6: 4.0356889e+11 | I6: 1.9075232e+11 | J6: 1.8613388e+11 | K6: 2.271042e+13 | L6: 2.4395439e+11 | M6: 1.4661108e+11 | O6: 2.4661737e+13 | P6: =+F6-O6 -> 0
B7: 2024-06 | C7: =DATE(LEFT(B7,4),RIGHT(B7,2),1) -> 45444 | D7: =ISNUMBER(C7) -> TRUE | E7: =+(J7+M7)/F7 -> 0.010710684 | F7: =SUM(G7:M7) -> 2.4267441e+13 | G7: 8.5371164e+11 | H7: 3.1391996e+11 | I7: 1.9005993e+11 | J7: 1.3905103e+11 | K7: 2.2418125e+13 | L7: 2.3170332e+11 | M7: 1.2086986e+11 | O7: 2.4267441e+13 | P7: =+F7-O7 -> 0
B8: 2024-07 | C8: =DATE(LEFT(B8,4),RIGHT(B8,2),1) -> 45474 | D8: =ISNUMBER(C8) -> TRUE | E8: =+(J8+M8)/F8 -> 0.010953393 | F8: =SUM(G8:M8) -> 2.4414825e+13 | G8: 7.2362464e+11 | H8: 3.6640025e+11 | I8: 1.7128046e+11 | J8: 1.4094648e+11 | K8: 2.2653495e+13 | L8: 2.325997e+11 | M8: 1.2647869e+11 | O8: 2.4414825e+13 | P8: =+F8-O8 -> 0
B9: 2024-08 | C9: =DATE(LEFT(B9,4),RIGHT(B9,2),1) -> 45505 | D9: =ISNUMBER(C9) -> TRUE | E9: =+(J9+M9)/F9 -> 0.011597034 | F9: =SUM(G9:M9) -> 2.4752557e+13 | G9: 8.3869398e+11 | H9: 3.8298886e+11 | I9: 2.1929032e+11 | J9: 1.494829e+11 | K9: 2.2780479e+13 | L9: 2.4404839e+11 | M9: 1.3757335e+11 | O9: 2.4752557e+13 | P9: =+F9-O9 -> 0
B10: 2024-09 | C10: =DATE(LEFT(B10,4),RIGHT(B10,2),1) -> 45536 | D10: =ISNUMBER(C10) -> TRUE | E10: =+(J10+M10)/F10 -> 0.012029055 | F10: =SUM(G10:M10) -> 2.4888817e+13 | G10: 8.5223885e+11 | H10: 3.5264144e+11 | I10: 1.953087e+11 | J10: 1.6638185e+11 | K10: 2.294368e+13 | L10: 2.455594e+11 | M10: 1.3300709e+11 | O10: 2.4888817e+13 | P10: =+F10-O10 -> 0
B11: 2024-10 | C11: =DATE(LEFT(B11,4),RIGHT(B11,2),1) -> 45566 | D11: =ISNUMBER(C11) -> TRUE | E11: =+(J11+M11)/F11 -> 0.011916556 | F11: =SUM(G11:M11) -> 2.483972e+13 | G11: 7.6497815e+11 | H11: 3.7023148e+11 | I11: 1.923126e+11 | J11: 1.672395e+11 | K11: 2.2983106e+13 | L11: 2.3308747e+11 | M11: 1.2876442e+11 | O11: 2.483972e+13 | P11: =+F11-O11 -> 0
B12: 2024-11 | C12: =DATE(LEFT(B12,4),RIGHT(B12,2),1) -> 45597 | D12: =ISNUMBER(C12) -> TRUE | E12: =+(J12+M12)/F12 -> 0.012037239 | F12: =SUM(G12:M12) -> 2.49269e+13 | G12: 8.5348002e+11 | H12: 3.278619e+11 | I12: 1.8991589e+11 | J12: 1.7964235e+11 | K12: 2.3018326e+13 | L12: 2.3726517e+11 | M12: 1.204087e+11 | O12: 2.49269e+13 | P12: =+F12-O12 -> 0
B13: 2024-12 | C13: =DATE(LEFT(B13,4),RIGHT(B13,2),1) -> 45627 | D13: =ISNUMBER(C13) -> TRUE | E13: =+(J13+M13)/F13 -> 0.01191713 | F13: =SUM(G13:M13) -> 2.5044834e+13 | G13: 7.8687758e+11 | H13: 3.6517494e+11 | I13: 1.7555787e+11 | J13: 1.8172086e+11 | K13: 2.318877e+13 | L13: 2.299906e+11 | M13: 1.1674167e+11 | O13: 2.5044834e+13 | P13: =+F13-O13 -> 0
... B26: 2026-01 | C26: =DATE(LEFT(B26,4),RIGHT(B26,2),1) -> 46023 | D26: =ISNUMBER(C26) -> TRUE | E26: =+(J26+M26)/F26 -> 0.0099209687 | F26: =SUM(G26:M26) -> 2.2384778e+13 | G26: 6.9370261e+11 | H26: 3.0341445e+11 | I26: 1.6559191e+11 | J26: 1.4898408e+11 | K26: 2.076483e+13 | L26: 2.3515977e+11 | M26: 7.3094601e+10 | O26: 2.2384778e+13 | P26: =+F26-O26 -> 0

Sheet TPM
B1: Tasa de política monetaria
B2: Para operaciones en moneda nacional del Banco Central de Costa Rica (BCCR)
C5: 2006 | D5: 2007 | E5: 2008 | F5: 2009 | G5: 2010 | H5: 2011 | I5: 2012 | J5: 2013 | K5: 2014 | L5: 2015 | M5: 2016 | N5: 2017 | O5: 2018 | P5: 2019 | Q5: 2020 | R5: 2021 | S5: 2022 | T5: 2023 | U5: 2024 | V5: 2025 | W5: 2026
B6: 1 Ene | F6: 10 | G6: 9 | H6: 6.5 | I6: 5 | J6: 5 | K6: 3.75 | L6: 5.25 | M6: 2.25 | N6: 1.75 | O6: 4.75 | P6: 5.25 | Q6: 2.75 | R6: 0.75 | S6: 1.25 | T6: 9 | U6: 6 | V6: 4 | W6: 3.25
B7: 2 Ene | D7: 8.97 | E7: 5.52 | F7: 10 | G7: 9 | H7: 6.5 | I7: 5 | J7: 5 | K7: 3.75 | L7: 5.25 | M7: 2.25 | N7: 1.75 | O7: 4.75 | P7: 5.25 | Q7: 2.75 | R7: 0.75 | S7: 1.25 | T7: 9 | U7: 6 | V7: 4 | W7: 3.25
B8: 3 Ene | D8: 8.97 | E8: 5.52 | F8: 10 | G8: 9 | H8: 6.5 | I8: 5 | J8: 5 | K8: 3.75 | L8: 5.25 | M8: 2.25 | N8: 1.75 | O8: 4.75 | P8: 5.25 | Q8: 2.75 | R8: 0.75 | S8: 1.25 | T8: 9 | U8: 6 | V8: 4 | W8: 3.25
B9: 4 Ene | D9: 8.97 | E9: 5.52 | F9: 10 | G9: 9 | H9: 6.5 | I9: 5 | J9: 5 | K9: 3.75 | L9: 5.25 | M9: 1.75 | N9: 1.75 | O9: 4.75 | P9: 5.25 | Q9: 2.75 | R9: 0.75 | S9: 1.25 | T9: 9 | U9: 6 | V9: 4 | W9: 3.25
B10: 5 Ene | D10: 8.97 | F10: 10 | G10: 9 | H10: 6.5 | I10: 5 | J10: 5 | K10: 3.75 | L10: 5.25 | M10: 1.75 | N10: 1.75 | O10: 4.75 | P10: 5.25 | Q10: 2.75 | R10: 0.75 | S10: 1.25 | T10: 9 | U10: 6 | V10: 4 | W10: 3.25
B11: 6 Ene | F11: 10 | G11: 9 | H11: 6.5 | I11: 5 | J11: 5 | K11: 3.75 | L11: 5.25 | M11: 1.75 | N11: 1.75 | O11: 4.75 | P11: 5.25 | Q11: 2.75 | R11: 0.75 | S11: 1.25 | T11: 9 | U11: 6 | V11: 4 | W11: 3.25
B12: 7 Ene | E12: 5.52 | F12: 10 | G12: 9 | H12: 6.5 | I12: 5 | J12: 5 | K12: 3.75 | L12: 5.25 | M12: 1.75 | N12: 1.75 | O12: 4.75 | P12: 5.25 | Q12: 2.75 | R12: 0.75 | S12: 1.25 | T12: 9 | U12: 6 | V12: 4 | W12: 3.25
B13: 8 Ene | D13: 8.97 | E13: 5.52 | F13: 10 | G13: 9 | H13: 6.5 | I13: 5 | J13: 5 | K13: 3.75 | L13: 5.25 | M13: 1.75 | N13: 1.75 | O13: 4.75 | P13: 5.25 | Q13: 2.75 | R13: 0.75 | S13: 1.25 | T13: 9 | U13: 6 | V13: 4 | W13: 3.25
B14: 9 Ene | D14: 8.97 | E14: 5.52 | F14: 10 | G14: 9 | H14: 6.5 | I14: 5 | J14: 5 | K14: 3.75 | L14: 5.25 | M14: 1.75 | N14: 1.75 | O14: 4.75 | P14: 5.25 | Q14: 2.75 | R14: 0.75 | S14: 1.25 | T14: 9 | U14: 6 | V14: 4 | W14: 3.25
B15: 10 Ene | D15: 8.97 | E15: 5.52 | F15: 10 | G15: 9 | H15: 6.5 | I15: 5 | J15: 5 | K15: 3.75 | L15: 5.25 | M15: 1.75 | N15: 1.75 | O15: 4.75 | P15: 5.25 | Q15: 2.75 | R15: 0.75 | S15: 1.25 | T15: 9 | U15: 6 | V15: 4 | W15: 3.25
B16: 11 Ene | D16: 8.97 | E16: 5.52 | F16: 10 | G16: 9 | H16: 6.5 | I16: 5 | J16: 5 | K16: 3.75 | L16: 5.25 | M16: 1.75 | N16: 1.75 | O16: 4.75 | P16: 5.25 | Q16: 2.75 | R16: 0.75 | S16: 1.25 | T16: 9 | U16: 6 | V16: 4 | W16: 3.25
B17: 12 Ene | D17: 8.97 | F17: 10 | G17: 9 | H17: 6.5 | I17: 5 | J17: 5 | K17: 3.75 | L17: 5.25 | M17: 1.75 | N17: 1.75 | O17: 4.75 | P17: 5.25 | Q17: 2.75 | R17: 0.75 | S17: 1.25 | T17: 9 | U17: 6 | V17: 4 | W17: 3.25
B18: 13 Ene | F18: 10 | G18: 9 | H18: 6.5 | I18: 5 | J18: 5 | K18: 3.75 | L18: 5.25 | M18: 1.75 | N18: 1.75 | O18: 4.75 | P18: 5.25 | Q18: 2.75 | R18: 0.75 | S18: 1.25 | T18: 9 | U18: 6 | V18: 4 | W18: 3.25
B19: 14 Ene | E19: 5.52 | F19: 10 | G19: 9 | H19: 6.5 | I19: 5 | J19: 5 | K19: 3.75 | L19: 5.25 | M19: 1.75 | N19: 1.75 | O19: 4.75 | P19: 5.25 | Q19: 2.75 | R19: 0.75 | S19: 1.25 | T19: 9 | U19: 6 | V19: 4 | W19: 3.25
B20: 15 Ene | D20: 8.97 | E20: 5.52 | F20: 10 | G20: 9 | H20: 6.5 | I20: 5 | J20: 5 | K20: 3.75 | L20: 5.25 | M20: 1.75 | N20: 1.75 | O20: 4.75 | P20: 5.25 | Q20: 2.75 | R20: 0.75 | S20: 1.25 | T20: 9 | U20: 6 | V20: 4 | W20: 3.25
B21: 16 Ene | D21: 8.97 | E21: 5.52 | F21: 10 | G21: 9 | H21: 6.5 | I21: 5 | J21: 5 | K21: 3.75 | L21: 5.25 | M21: 1.75 | N21: 1.75 | O21: 4.75 | P21: 5.25 | Q21: 2.75 | R21: 0.75 | S21: 1.25 | T21: 9 | U21: 6 | V21: 4 | W21: 3.25
B22: 17 Ene | D22: 8.97 | E22: 5.52 | F22: 10 | G22: 9 | H22: 6.5 | I22: 5 | J22: 5 | K22: 3.75 | L22: 5.25 | M22: 1.75 | N22: 1.75 | O22: 4.75 | P22: 5.25 | Q22: 2.75 | R22: 0.75 | S22: 1.25 | T22: 9 | U22: 6 | V22: 4 | W22: 3.25
B23: 18 Ene | D23: 8.97 | E23: 5.52 | F23: 10 | G23: 9 | H23: 6.5 | I23: 5 | J23: 5 | K23: 3.75 | L23: 5.25 | M23: 1.75 | N23: 1.75 | O23: 4.75 | P23: 5.25 | Q23: 2.75 | R23: 0.75 | S23: 1.25 | T23: 9 | U23: 6 | V23: 4 | W23: 3.25
B24: 19 Ene | D24: 8.97 | F24: 10 | G24: 9 | H24: 6.5 | I24: 5 | J24: 5 | K24: 3.75 | L24: 5.25 | M24: 1.75 | N24: 1.75 | O24: 4.75 | P24: 5.25 | Q24: 2.75 | R24: 0.75 | S24: 1.25 | T24: 9 | U24: 5.75 | V24: 4 | W24: 3.25
B25: 20 Ene | F25: 10 | G25: 9 | H25: 6.5 | I25: 5 | J25: 5 | K25: 3.75 | L25: 5.25 | M25: 1.75 | N25: 1.75 | O25: 4.75 | P25: 5.25 | Q25: 2.75 | R25: 0.75 | S25: 1.25 | T25: 9 | U25: 5.75 | V25: 4 | W25: 3.25
B26: 21 Ene | E26: 5.52 | F26: 10 | G26: 9 | H26: 6.5 | I26: 5 | J26: 5 | K26: 3.75 | L26: 5.25 | M26: 1.75 | N26: 1.75 | O26: 4.75 | P26: 5.25 | Q26: 2.75 | R26: 0.75 | S26: 1.25 | T26: 9 | U26: 5.75 | V26: 4 | W26: 3.25
B27: 22 Ene | D27: 8.97 | E27: 5.52 | F27: 10 | G27: 9 | H27: 6.5 | I27: 5 | J27: 5 | K27: 3.75 | L27: 5.25 | M27: 1.75 | N27: 1.75 | O27: 4.75 | P27: 5.25 | Q27: 2.75 | R27: 0.75 | S27: 1.25 | T27: 9 | U27: 5.75 | V27: 4 | W27: 3.25
B28: 23 Ene | D28: 8.97 | E28: 5.52 | F28: 10 | G28: 9 | H28: 6.5 | I28: 5 | J28: 5 | K28: 3.75 | L28: 5.25 | M28: 1.75 | N28: 1.75 | O28: 4.75 | P28: 5.25 | Q28: 2.75 | R28: 0.75 | S28: 1.25 | T28: 9 | U28: 5.75 | V28: 4 | W28: 3.25
B29: 24 Ene | D29: 8.97 | E29: 5.52 | F29: 10 | G29: 9 | H29: 6.5 | I29: 5 | J29: 5 | K29: 3.75 | L29: 5.25 | M29: 1.75 | N29: 1.75 | O29: 4.75 | P29: 5.25 | Q29: 2.75 | R29: 0.75 | S29: 1.25 | T29: 9 | U29: 5.75 | V29: 4 | W29: 3.25
B30: 25 Ene | D30: 8.97 | E30: 5.52 | F30: 10 | G30: 9 | H30: 6.5 | I30: 5 | J30: 5 | K30: 3.75 | L30: 5.25 | M30: 1.75 | N30: 1.75 | O30: 4.75 | P30: 5.25 | Q30: 2.75 | R30: 0.75 | S30: 1.25 | T30: 9 | U30: 5.75 | V30: 4 | W30: 3.25
B31: 26 Ene | D31: 8.97 | F31: 10 | G31: 9 | H31: 6.5 | I31: 5 | J31: 5 | K31: 3.75 | L31: 5.25 | M31: 1.75 | N31: 1.75 | O31: 4.75 | P31: 5.25 | Q31: 2.75 | R31: 0.75 | S31: 1.25 | T31: 9 | U31: 5.75 | V31: 4 | W31: 3.25
B32: 27 Ene | F32: 10 | G32: 9 | H32: 6.5 | I32: 5 | J32: 5 | K32: 3.75 | L32: 5.25 | M32: 1.75 | N32: 1.75 | O32: 4.75 | P32: 5.25 | Q32: 2.75 | R32: 0.75 | S32: 1.75 | T32: 9 | U32: 5.75 | V32: 4 | W32: 3.25
B33: 28 Ene | E33: 5.52 | F33: 10 | G33: 9 | H33: 6.5 | I33: 5 | J33: 5 | K33: 3.75 | L33: 5.25 | M33: 1.75 | N33: 1.75 | O33: 4.75 | P33: 5.25 | Q33: 2.75 | R33: 0.75 | S33: 1.75 | T33: 9 | U33: 5.75 | V33: 4 | W33: 3.25
B34: 29 Ene | D34: 8.97 | E34: 5.52 | F34: 10 | G34: 9 | H34: 6.5 | I34: 5 | J34: 5 | K34: 3.75 | L34: 5.25 | M34: 1.75 | N34: 1.75 | O34: 4.75 | P34: 5.25 | Q34: 2.75 | R34: 0.75 | S34: 1.75 | T34: 9 | U34: 5.75 | V34: 4 | W34: 3.25
B35: 30 Ene | D35: 5.98 | E35: 5.52 | F35: 10 | G35: 9 | H35: 6.5 | I35: 5 | J35: 5 | K35: 3.75 | L35: 5.25 | M35: 1.75 | N35: 1.75 | O35: 4.75 | P35: 5.25 | Q35: 2.25 | R35: 0.75 | S35: 1.75 | T35: 9 | U35: 5.75 | V35: 4 | W35: 3.25
B36: 31 Ene | D36: 5.98 | E36: 5.99 | F36: 10 | G36: 9 | H36: 6.5 | I36: 5 | J36: 5 | K36: 3.75 | L36: 5.25 | M36: 1.75 | N36: 1.75 | O36: 4.75 | P36: 5.25 | Q36: 2.25 | R36: 0.75 | S36: 1.75 | T36: 9 | U36: 5.75 | V36: 4 | W36: 3.25
B37: 1 Feb | D37: 5.98 | E37: 5.99 | F37: 10 | G37: 9 | H37: 6.5 | I37: 5 | J37: 5 | K37: 3.75 | L37: 5.25 | M37: 1.75 | N37: 1.75 | O37: 5 | P37: 5.25 | Q37: 2.25 | R37: 0.75 | S37: 1.75 | T37: 9 | U37: 5.75 | V37: 4 | W37: 3.25
B38: 2 Feb | D38: 5.98 | F38: 10 | G38: 9 | H38: 6.5 | I38: 5 | J38: 5 | K38: 3.75 | L38: 4.75 | M38: 1.75 | N38: 1.75 | O38: 5 | P38: 5.25 | Q38: 2.25 | R38: 0.75 | S38: 1.75 | T38: 9 | U38: 5.75 | V38: 4 | W38: 3.25
B39: 3 Feb | F39: 10 | G39: 9 | H39: 6.5 | I39: 5 | J39: 5 | K39: 3.75 | L39: 4.75 | M39: 1.75 | N39: 1.75 | O39: 5 | P39: 5.25 | Q39: 2.25 | R39: 0.75 | S39: 1.75 | T39: 9 | U39: 5.75 | V39: 4 | W39: 3.25
B40: 4 Feb | E40: 5.99 | F40: 10 | G40: 9 | H40: 6.5 | I40: 5 | J40: 5 | K40: 3.75 | L40: 4.75 | M40: 1.75 | N40: 1.75 | O40: 5 | P40: 5.25 | Q40: 2.25 | R40: 0.75 | S40: 1.75 | T40: 9 | U40: 5.75 | V40: 4 | W40: 3.25
B41: 5 Feb | D41: 5.98 | E41: 5.99 | F41: 10 | G41: 9 | H41: 6.5 | I41: 5 | J41: 5 | K41: 3.75 | L41: 4.75 | M41: 1.75 | N41: 1.75 | O41: 5 | P41: 5.25 | Q41: 2.25 | R41: 0.75 | S41: 1.75 | T41: 9 | U41: 5.75 | V41: 4 | W41: 3.25
B42: 6 Feb | D42: 5.98 | E42: 5.99 | F42: 10 | G42: 9 | H42: 6.5 | I42: 5 | J42: 5 | K42: 3.75 | L42: 4.75 | M42: 1.75 | N42: 1.75 | O42: 5 | P42: 5.25 | Q42: 2.25 | R42: 0.75 | S42: 1.75 | T42: 9 | U42: 5.75 | V42: 4 | W42: 3.25
...

Sheet Tipo de cambio
B1: Tipo de cambio de venta del dólar de los Estados Unidos de América
B2: En colones costarricenses (Referencia del Banco Central de Costa Rica)
B5: Fecha | C5: Tipo cambio venta | F5: Average of Tipo cambio venta | G5: Column Labels
B6: 45292 | C6: 526.88 | F6: Row Labels | G6: 2024 | H6: 2025 | I6: 2026 | J6: Grand Total
B7: 45293 | C7: 526.88 | F7: Jan | G7: 521.51581 | H7: 508.67452 | I7: 497.94419 | J7: 509.37817
B8: 45294 | C8: 525.68 | F8: Feb | G8: 519.45862 | H8: 509.92357 | I8: 492.85444 | J8: 509.51387
B9: 45295 | C9: 524.65 | F9: Mar | G9: 510.02129 | H9: 504.40355 | J9: 507.21242
B10: 45296 | C10: 523.83 | F10: Apr | G10: 504.981 | H10: 508.35533 | J10: 506.66817
B11: 45297 | C11: 524.73 | F11: May | G11: 515.43742 | H11: 509.32806 | J11: 512.38274
B12: 45298 | C12: 524.73 | F12: Jun | G12: 528.993 | H12: 508.63633 | J12: 518.81467
B13: 45299 | C13: 524.73 | F13: Jul | G13: 529.24774 | H13: 507.23484 | J13: 518.24129
B14: 45300 | C14: 525.27 | F14: Aug | G14: 525.70355 | H14: 507.73548 | J14: 516.71952
B15: 45301 | C15: 524.94 | F15: Sep | G15: 522.019 | H15: 507.50667 | J15: 514.76283
B16: 45302 | C16: 524.97 | F16: Oct | G16: 518.64903 | H16: 506.00194 | J16: 512.32548
B17: 45303 | C17: 523.15 | F17: Nov | G17: 513.608 | H17: 502.41 | J17: 508.009
B18: 45304 | C18: 523.3 | F18: Dec | G18: 509.1371 | H18: 497.75968 | J18: 503.44839
B19: 45305 | C19: 523.3 | F19: Grand Total | G19: 518.23333 | H19: 506.46682 | I19: 496.07449 | J19: 511.33518
B20: 45306 | C20: 523.3
B21: 45307 | C21: 521.13
B22: 45308 | C22: 519.39
B23: 45309 | C23: 520.16
B24: 45310 | C24: 519.23
B25: 45311 | C25: 519.36
B26: 45312 | C26: 519.36
B27: 45313 | C27: 519.36
B28: 45314 | C28: 518.32
B29: 45315 | C29: 517.72
B30: 45316 | C30: 517.5
B31: 45317 | C31: 517.07
... B785: 46071 | C785: 484.62

Sheet Inflación
B1: Índice de precios al consumidor (IPC)
B2: Diciembre 2020=100
B3: Niveles y variaciones
C5: Nivel | D5: Variación mensual (%) | E5: Variación interanual (%) | F5: Variación acumulada (%)/n3
B6: Enero/2024 | C6: 109.52907 | D6: 0.05509727 | E6: -1.868634 | F6: 0.05509726
B7: Febrero/2024 | C7: 109.41111 | D7: -0.10768991 | E7: -1.131406 | F7: -0.05265197
B8: Marzo/2024 | C8: 109.10053 | D8: -0.28387174 | E8: -1.1863148 | F8: -0.33637426
B9: Abril/2024 | C9: 109.45778 | D9: 0.32745448 | E9: -0.52081297 | F9: -0.01002126
B10: Mayo/2024 | C10: 109.54703 | D10: 0.08153899 | E10: -0.33476582 | F10: 0.07150957
B11: Junio/2024 | C11: 109.70548 | D11: 0.14464296 | E11: -0.03375699 | F11: 0.21625596
B12: Julio/2024 | C12: 109.57205 | D12: -0.12163323 | E12: 0.03187455 | F12: 0.09435969
B13: Agosto/2024 | C13: 109.6982 | D13: 0.11513259 | E13: 0.31250425 | F13: 0.20960092
B14: Septiembre/2024 | C14: 109.33301 | D14: -0.33290372 | E14: -0.13585182 | F14: -0.12400057
B15: Octubre/2024 | C15: 108.84745 | D15: -0.44411085 | E15: -0.7863946 | F15: -0.56756072
B16: Noviembre/2024 | C16: 109.35763 | D16: 0.4687144 | E16: -0.09182255 | F16: -0.10150656
B17: Diciembre/2024 | C17: 110.39017 | D17: 0.94418427 | E17: 0.8417193 | F17: 0.8417193
... B30: Enero/2026 | C30: 107.9854 | D30: -0.96346918 | E30: -2.5307416 | F30: -0.96346918
