Workbook

Sheet IS
B1: DELTA AIR LINES, INC.
B2: CONSOLIDATED STATEMENTS OF OPERATIONS
B3: Years Ended December 31, 2024 and December 31, 2025
C6: For the Years Ended December 31, in millions
C7: 2024 | D7: 2025
B9: Passenger | C9: 50894 | D9: 51768
B10: Cargo | C10: 822 | D10: 900
B11: Other | C11: 9927 | D11: 10696
B12: Gross Profit | C12: =SUM(C9:C11) -> 61643 | D12: =SUM(D9:D11) -> 63364
B13: Salaries and related costs | C13: 16161 | D13: 17520
B14: Aircraft fuel and related taxes | C14: 10566 | D14: 9819
B15: Ancillary businesses and refinery | C15: 5416 | D15: 5987
B16: Contracted services | C16: 4228 | D16: 4617
B17: Landing fees and other rents | C17: 3150 | D17: 3564
B18: Regional carrier expense | C18: 2328 | D18: 2553
B19: Passenger commissions and | C19: 2485 | D19: 2485
B20: Depreciation and amortization | C20: 2513 | D20: 2443
B21: Aircraft maintenance materials | C21: 2616 | D21: 2432
B22: Passenger service | C22: 1788 | D22: 1855
B23: Profit sharing | C23: 1389 | D23: 1337
B24: Aircraft rent | C24: 548 | D24: 542
... B26: Other | C26: 2460 | D26: 2388
B27: Total operating expenses | C27: =SUM(C13:C26) -> 55648 | D27: =SUM(D13:D26) -> 57542
B28: EBITDA | C28: =+C29+C20 -> 8508 | D28: =+D29+D20 -> 8265
B29: Operating income (EBIT) | C29: =+C12-C27 -> 5995 | D29: =+D12-D27 -> 5822
B30: Interest expense, net | C30: -747 | D30: -679
B31: Gain/(loss) on investments, net | C31: -319 | D31: 1212
B32: Loss on extinguishment of debt | C32: -39 | D32: -26
B33: Miscellaneous, net | C33: -232 | D33: -144
B34: Non-Operating Income/(Expense) | C34: =SUM(C30:C33) -> -1337 | D34: =SUM(D30:D33) -> 363
B35: EBT | C35: =+C29+C34 -> 4658 | D35: =+D29+D34 -> 6185
B36: Income tax expense | C36: -1201 | D36: -1180
B37: Net income | C37: =+C35+C36 -> 3457 | D37: =+D35+D36 -> 5005
B38: Basic Earnings Per Share | C38: 5.39 | D38: 7.72
B39: Diluted Earnings Per Share | C39: 5.33 | D39: 7.66

Sheet BS
B1: DELTA AIR LINES, INC.
B2: CONSOLIDATED BALANCE SHEETS
B3: As of December 31, 2024 and December 31, 2023
H4: December 31, in millions
H5: 2024 | I5: 2025
B6: Assets
B7: Cash and cash equivalents | H7: 3069 | I7: 4310 | M7: =+H19-H45 -> 0 | N7: =+I19-I45 -> 0
B8: Accounts receivable | H8: 3224 | I8: 2850
B9: Fuel, expendable parts and supplies inventories, net of an allowance for obsolescence of $124 and $120 | H9: 1428 | I9: 1601
B10: Prepaid expenses | H10: 2123 | I10: 2207
B11: Total current assets | H11: =SUM(H7:H10) -> 9844 | I11: =SUM(I7:I10) -> 10968
B12: Property and equipment, net of accumulated depreciation and amortization of $24,719 and $23,228 | H12: 37595 | I12: 39743
B13: Operating lease right-of-use assets | H13: 6644 | I13: 6244
B14: Goodwill | H14: 9753 | I14: 9753
B15: Identifiable intangibles, net of accumulated amortization of $928 and $919 | H15: 5975 | I15: 5966
B16: Equity investments | H16: 2846 | I16: 4222
B17: Other noncurrent assets | H17: 2715 | I17: 4421
B18: Total non-current assets | H18: =SUM(H12:H17) -> 65528 | I18: =SUM(I12:I17) -> 70349
B19: Total assets | H19: =+H18+H11 -> 75372 | I19: =+I18+I11 -> 81317
B21: Liabilities and Partners' Equity
B22: Current maturities of debt and finance leases | H22: 2175 | I22: 1605
B23: Current maturities of operating leases | H23: 763 | I23: 809
B24: Air traffic liability | H24: 7094 | I24: 7157
B25: Accounts payable | H25: 4650 | I25: 5226
B26: Accrued salaries and related benefits | H26: 4762 | I26: 4906
B27: Loyalty program deferred revenue | H27: 4314 | I27: 4876
B28: Fuel card obligation | H28: 1100 | I28: 1100
B29: Other accrued liabilities | H29: 1812 | I29: 1945
B30: Total current liabilities | H30: =SUM(H22:H29) -> 26670 | I30: =SUM(I22:I29) -> 27624
B31: Debt and finance leases | H31: 14019 | I31: 12507
B32: Noncurrent operating leases | H32: 5814 | I32: 5353
B33: Pension, postretirement and related benefits | H33: 3144 | I33: 3156
B34: Loyalty program deferred revenue | H34: 4512 | I34: 4386
B35: Deferred income taxes, net | H35: 2176 | I35: 3444
B36: Other noncurrent liabilities | H36: 3744 | I36: 3994
B37: Total non-current liabilities | H37: =SUM(H31:H36) -> 33409 | I37: =SUM(I31:I36) -> 32840
B38: Total liabilities | H38: =+H37+H30 -> 60079 | I38: =+I37+I30 -> 60464
B39: Common stock at $0.0001 par value; 1,500,000,000 shares authorized, 659,669,346 and 654,571,606 shares issued | H39: 0 | I39: 0
B40: Additional paid-in capital | H40: 11740 | I40: 11883
B41: Retained earnings | H41: 8783 | I41: 13343
...

Sheet CF
B1: DELTA AIR LINES, INC.
B2: CONSOLIDATED STATEMENTS OF OPERATIONS
B3: Years Ended December 31, 2024 and December 31, 2023
C6: For the Years Ended December 31, in millions
C7: 2024 | D7: 2025
B8: Cash Flows From Operating Activities
B9: Net income | C9: 3457 | D9: 5005
B10: Adjustments to reconcile net income to net cash provided by operating activities
B11: Depreciation and amortization | C11: 2513 | D11: 2443
B12: Deferred income taxes | C12: 1155 | D12: 1109
B13: (Gain)/loss on fair value investments | C13: 323 | D13: -1209
B14: Pension, postretirement and postemployment payments greater than expense | C14: -296 | D14: -210
B15: Changes in certain assets and liabilities
B16: Receivables | C16: -126 | D16: 432
B17: Prepaids and other current assets | C17: -241 | D17: -183
B18: Air traffic liability | C18: 50 | D18: 63
B19: Loyalty program deferred revenue | C19: 407 | D19: 435
B20: Profit sharing | C20: 6 | D20: -53
B21: Other payables, deferred revenue and accrued liabilities | C21: 614 | D21: 842
B22: Other, net | C22: 163 | D22: -332
B23: Net cash provided by operating activities | C23: =SUM(C16:C22,C9,C11:C14) -> 8025 | D23: =SUM(D16:D22,D9,D11:D14) -> 8342
B24: Cash Flows From Investing Activities
B25: Property and equipment additions:
B26: Flight equipment, including advance payments | C26: -3914 | D26: -3521
B27: Ground property and equipment, including technology | C27: -1226 | D27: -978
B28: Purchase of equity investments | C28: 0 | D28: -276
B29: Purchase of short-term investments | C29: 0 | D29: 0
B30: Redemption of short-term investments | C30: 1137 | D30: 0
B31: Other, net | C31: 264 | D31: 589
B32: Net cash used in investing activities | C32: =SUM(C26:C31) -> -3739 | D32: =SUM(D26:D31) -> -4186
B33: Cash Flows From Financing Activities
B34: Property and equipment additions:
B35: Proceeds from long-term obligations | C35: 0 | D35: 2215
B36: Payments on debt and finance lease obligations | C36: -3953 | D36: -4827
B37: Cash dividends | C37: -321 | D37: -440
B38: Other, net | C38: 14 | D38: -24
B39: Net cash used in financing activities | C39: =SUM(C35:C38) -> -4260 | D39: =SUM(D35:D38) -> -3076
B40: Net Increase/(Decrease) in Cash, Cash Equivalents and Restricted Cash | C40: 26 | D40: 1080
B41: Cash, cash equivalents and restricted cash at beginning of | C41: 3395 | D41: 3421
B42: Cash, cash equivalents and restricted cash at end of period | C42: =SUM(C40:C41) -> 3421 | D42: =SUM(D40:D41) -> 4501
...

Sheet Análisis Financiero
B1: Recordar, datos en millones de USD
B3: Ratios | D3: 2024 | E3: 2025 | I3: Growth Metrics (g) | K3: 2024
B4: Liquidity | I4: Revenues | K4: =+(IS!D9-IS!C9)/IS!C9 -> 0.017172948
B5: Current Ratio | D5: =+BS!H11/BS!H30 -> 0.36910386 | E5: =+BS!I11/BS!I30 -> 0.39704605 | I5: SGA | K5: =+(IS!D27-IS!C27)/IS!C27 -> 0.034035365
B6: OWK Credit formula = Activos Operativos CP - Pasivos Operativos CP | D6: =+BS!H8+BS!H9+BS!H10-(BS!H25+BS!H26+BS!H24+BS!H27+BS!H28+BS!H29) -> -16957 | E6: =+BS!I8+BS!I9+BS!I10-(BS!I25+BS!I26+BS!I24+BS!I27+BS!I28+BS!I29) -> -18552 | I6: Gross Margin | K6: =+((E10-D10)/D10) -> 0.010564452
B7: Cambio en OWK | E7: =+E6-D6 -> -1595 | I7: Operating Margin | K7: =+((E11-D11)/D11) -> -0.045253198
I8: Net Margin | K8: =+((E12-D12)/D12) -> 0.42334409
B9: Profitability | I9: SGA/Revenues | K9: =+((E23-D23))/D23 -> 0.065788599
B10: Gross Margin | D10: =+IS!C12/IS!C9 -> 1.2112037 | E10: =+IS!D12/IS!D9 -> 1.2239994 | I10: OWK/Revenues | K10: =+(E24-D24)/D24 -> 0.075590392
B11: Operating Margin | D11: =+IS!C29/IS!C9 -> 0.11779385 | E11: =+IS!D29/IS!D9 -> 0.1124633 | I11: IC/Revenues | K11: =+(E25-D25)/D25 -> -0.16291971
B12: Net Margin | D12: =+IS!C37/IS!C9 -> 0.067925492 | E12: =+IS!D37/IS!D9 -> 0.096681348 | I12: OCF | K12: =+(CF!D23-CF!C23)/CF!C23 -> 0.039501558
B13: ROE | E13: =+IS!#REF!/BS!I44 -> #REF!
B14: ROA | D14: =+IS!#REF!/BS!H19 -> #REF! | E14: =+IS!#REF!/BS!I19 -> #REF!
B15: Tau normalizado | C15: =+ABS(IS!C36/IS!C37) -> 0.34741105 | D15: =+C15 -> 0.34741105 | I15: Capex | K15: =+-((F56-E56)/F56) -> 0.14247611
B16: NOPAT = EBIT * (1-Tau(25%)) | D16: =+(1-$C$15)*IS!C29 -> 3912.2708 | E16: =+(1-$C$15)*IS!D29 -> 3799.3729 | I16: FCF | K16: =+(F57-E57)/F57 -> 0.24928441
B17: ROIC (Tau 25%) | E17: =+E16/D42 -> 0.078658707 | I17: Current Ratio | K17: =+(E5-D5)/E5 -> 0.070375175
B18: Tau 2024 | C18: =+ABS(#REF!) -> #REF!
B19: NOPAT = EBIT * (1-Tau(25%)) | D19: =+(1-$C$18)*IS!D29 -> #REF! | E19: =+(1-C18)*IS!D29 -> #REF!
B20: ROIC (Tau 4.56%) | E20: =+E19/D42 -> #REF!
I21: OWK | K21: =+-(E6-D6)/E6 -> -0.085974558
B22: Operational Efficiency
B23: SGA/Revenues | D23: =+IS!C13/IS!C9 -> 0.31754234 | E23: =+IS!D13/IS!D9 -> 0.33843301
B24: OWK/Revenues | D24: =+D6/IS!C9 -> -0.33318269 | E24: =+E6/IS!D9 -> -0.3583681
B25: IC/Revenues | D25: =+D42/IS!C9 -> 0.94907062 | E25: =+E42/IS!D9 -> 0.79444831
B26: COGS/Revenues | D26: =+IS!C11/IS!C9 -> 0.19505246 | E26: =+IS!D11/IS!D9 -> 0.20661412
B27: Depreciation/Revenues | D27: =+IS!C14/IS!C9 -> 0.20760797 | E27: =+IS!D14/IS!D9 -> 0.18967316
B28: PPE/Revenues | D28: =+BS!H12/IS!C9 -> 0.73869218 | E28: =+BS!I12/IS!D9 -> 0.76771365
B29: EBITDA/Revenues | D29: =+(IS!C29+IS!C14)/IS!C9 -> 0.32540182 | E29: =+(IS!D29+IS!D14)/IS!D9 -> 0.30213645
B30: EBIT/Revenues | D30: =+IS!C29/IS!C9 -> 0.11779385 | E30: =+IS!D29/IS!D9 -> 0.1124633
B32: Leverage
B33: BVD/BVE - D/E | D33: =+D45/D46 -> 2.1584385 | E33: =+E45/E46 -> 0.97223421
B34: Net debt | D34: =+D45-BS!H7 -> 29940 | E34: =+E45-BS!I7 -> 15964
B35: EBITDA | D35: =+IS!C29+IS!C14 -> 16561 | E35: =+IS!D29+IS!D14 -> 15641
B36: Net debt / EBITDA | D36: =+D34/D35 -> 1.8078618 | E36: =+E34/E35 -> 1.0206509
B38: Summarized Balance | H38: Pesos
B39: P, P & E | D39: 2024 | E39: 2025 | F39: Cambios | G39: g | H39: 2024 | I39: 2025
B40: OWK | D40: =+D45+D46-D41 -> 10707 | E40: =+E45+E46-E41 -> 1384 | F40: =+E40-D40 -> -9323 | G40: =+(E40-D40)/D40 -> -0.87073877 | H40: =+D40/D42 -> 0.22166784 | I40: =+E40/E42 -> 0.033651859
B41: Fixed Assests | D41: =+BS!H12 -> 37595 | E41: =+BS!I12 -> 39743 | F41: =+E41-D41 -> 2148 | G41: =+(E41-D41)/D41 -> 0.057135257 | H41: =+D41/D42 -> 0.77833216 | I41: =+E41/E42 -> 0.96634814
B42: Invested Capital | D42: =SUM(D40:D41) -> 48302 | E42: =SUM(E40:E41) -> 41127 | F42: =+E42-D42 -> -7175 | G42: =+(E42-D42)/D42 -> -0.14854457 | H42: =SUM(H40:H41) -> 1 | I42: =SUM(I40:I41) -> 1
B44: Deb/Equity
...

Sheet EL
B2: Moody's | C2: Baa2
B3: S&P | C3: BBB-
B5: Datos asumidos
B7: Escenarios basados en el nivel de pasivos totales de Delta
B9: Pesimista (Deuda financiera principal y se aumenta el default a 2%, suponiendo peor escenario) | E9: Conservador (incluyendo otros leases y demás) | H9: Optimista (asumiento que nota la exposición estaría disponible al incumplimiento)
B10: PD | C10: 0.02 | E10: PD | F10: 0.01 | H10: PD | I10: 0.01
B11: LDG | C11: 0.6 | E11: LDG | F11: 0.5 | H11: LDG | I11: 0.4
B12: EAD | C12: 30000000 | E12: EAD | F12: 25000000 | H12: EAD | I12: 20000000
B13: EL | C13: =+C10*C11*C12 -> 360000 | E13: EL | F13: =+F10*F11*F12 -> 125000 | H13: EL | I13: =+I10*I11*I12 -> 80000
B15: Peso de la EAD sobre la EL | C15: =+C13/C12 -> 0.012 | E15: Peso de la EAD sobre la EL | F15: =+F13/F12 -> 0.005 | H15: Peso de la EAD sobre la EL | I15: =+I13/I12 -> 0.004

Sheet Supuestos DCF - Múltiplo
B2: Datos usados del 2024
B3: Empresa | C3: Sterling Infrastructure, Inc. | D3: Granite Construction Incorporated | E3: Construction Partners, Inc.
B4: Ticker | C4: STRL | D4: GVA | E4: ROAD | F4: Promedio
B5: Tamaño y crecimiento
B6: Revenues | C6: =+#REF! -> #REF! | D6: =+#REF! -> #REF! | E6: =+#REF! -> #REF! | F6: =+AVERAGE(C6:E6) -> #REF!
B7: g (crecimiento) | C7: =+#REF! -> #REF! | D7: =+#REF! -> #REF! | E7: =+#REF! -> #REF! | F7: =+AVERAGE(C7:E7) -> #REF!
B8: Utilidad neta | C8: =+#REF! -> #REF! | D8: =+#REF! -> #REF! | E8: =+#REF! -> #REF! | F8: =+AVERAGE(C8:E8) -> #REF!
B9: Eficiencia operativa
B10: SGA | C10: =+#REF! -> #REF! | D10: =+#REF! -> #REF! | E10: =+#REF! -> #REF! | F10: =+AVERAGE(C10:E10) -> #REF!
B11: SGA/Revenues | C11: =+#REF! -> #REF! | D11: =+#REF! -> #REF! | E11: =+#REF! -> #REF! | F11: =+AVERAGE(C11:E11) -> #REF!
B12: COGS | C12: 1689633000 | D12: 3434877000 | E12: 1565635000 | F12: =+AVERAGE(C12:E12) -> 2.2300483e+09
B13: COGS/Revenues | C13: =+C12/C6 -> #REF! | D13: =+D12/D6 -> #REF! | E13: =+E12/E6 -> #REF! | F13: =+AVERAGE(C13:E13) -> #REF!
B14: OWK | C14: =+#REF! -> #REF! | D14: =+#REF! -> #REF! | E14: =+#REF! -> #REF! | F14: =+AVERAGE(C14:E14) -> #REF!
B15: OWK/Revenues | C15: =+C14/C6 -> #REF! | D15: =+D14/D6 -> #REF! | E15: =+E14/E6 -> #REF! | F15: =+AVERAGE(C15:E15) -> #REF!
B16: IC | C16: =+#REF! -> #REF! | D16: =+#REF! -> #REF! | E16: =+#REF! -> #REF! | F16: =+AVERAGE(C16:E16) -> #REF!
B17: IC/Revenues | C17: =+C16/C6 -> #REF! | D17: =+D16/D6 -> #REF! | E17: =+E16/E6 -> #REF! | F17: =+AVERAGE(C17:E17) -> #REF!
B18: Rentabilidad
B19: Margen Bruto | C19: =+#REF! -> #REF! | D19: =+#REF! -> #REF! | E19: =+#REF! -> #REF! | F19: =+AVERAGE(C19:E19) -> #REF!
B20: Margen Operativo | C20: =+#REF! -> #REF! | D20: =+#REF! -> #REF! | E20: =+#REF! -> #REF! | F20: =+AVERAGE(C20:E20) -> #REF!
B21: Margen Neto | C21: =+#REF! -> #REF! | D21: =+#REF! -> #REF! | E21: =+#REF! -> #REF! | F21: =+AVERAGE(C21:E21) -> #REF!
B22: Liquidez
B23: Current Ratio | C23: =+#REF! -> #REF! | D23: =+#REF! -> #REF! | E23: =+#REF! -> #REF! | F23: =+#REF! -> #REF!
B25: Cardinal
F26: Comentario
B27: Tau | C27: 0.25 | F27: Se asume constante
B28: Caso Pesimista
C29: 2023 | D29: 2024 | E29: Promedio | F29: Comentario
B30: Revenues | C30: =+IS!C9 -> 50894 | D30: =+IS!D9 -> 51768 | E30: =+AVERAGE(C30:D30) -> 51331 | F30: Crece de igual forma que el base, pero disminuye a un 3% en el último año, determinando el peor caso posible.
B31: EBIT/Revenues | C31: =+'Análisis Financiero'!D30 -> 0.11779385 | D31: =+'Análisis Financiero'!E30 -> 0.1124633 | E31: =+AVERAGE(C31:D31) -> 0.11512857 | F31: Se asume que baja un 1% en referencia a al promedio de la industria.
B32: EBITDA/Revenues | C32: =+'Análisis Financiero'!D29 -> 0.32540182 | D32: =+'Análisis Financiero'!E29 -> 0.30213645 | E32: =+AVERAGE(C32:D32) -> 0.31376914 | F32: Se asume que baja un 4% en referencia a al promedio de la industria.
B33: SGA/Revenues | C33: =+'Análisis Financiero'!D23 -> 0.31754234 | D33: =+'Análisis Financiero'!E23 -> 0.33843301 | E33: =+AVERAGE(C33:D33) -> 0.32798768 | F33: Se asume constante al promedio.
B34: D/Revenues | C34: =+'Análisis Financiero'!D27 -> 0.20760797 | D34: =+'Análisis Financiero'!E27 -> 0.18967316 | E34: =+AVERAGE(C34:D34) -> 0.19864056 | F34: Se asume constante al promedio.
B35: OWK/Revenues | C35: =+'Análisis Financiero'!D24 -> -0.33318269 | D35: =+'Análisis Financiero'!E24 -> -0.3583681 | E35: =+AVERAGE(C35:D35) -> -0.3457754 | F35: Se asume que aumenta al 10%, por el tema de expansión y adquicisiones.
B36: PPE/Revenues | C36: =+'Análisis Financiero'!D28 -> 0.73869218 | D36: =+'Análisis Financiero'!E28 -> 0.76771365 | E36: =+AVERAGE(C36:D36) -> 0.75320291 | F36: Se asume un incremento al 18%, dado a si falla su modelo de expansión, requiriendo mayor inversión en activos para sostener crecimiento.
B37: Caso Base
C38: 2023 | D38: 2024 | E38: Promedio | F38: Comentario
B39: Revenues | C39: =+C30 -> 50894 | D39: =+D30 -> 51768 | E39: =+E30 -> 51331 | F39: Se determina a un 27.13% y baja en relación a su aumento, en un 5% cada año, cercano al 6.3% de incremento de población que espera Cardinal y a su vez, similar al 5.3% del CAGR de la industria pronosticado hasta el 2035.
B40: EBIT/Revenues | C40: =+C31 -> 0.11779385 | D40: =+'Análisis Financiero'!E30 -> 0.1124633 | E40: =+E31 -> 0.11512857 | F40: Se asume que baja un 2% en referencia a al promedio de la industria.
B41: EBITDA/Revenues | C41: =+C32 -> 0.32540182 | D41: =+D32 -> 0.30213645 | E41: =+E32 -> 0.31376914 | F41: Se asume que baja un 2% en referencia a al promedio de la industria.
B42: SGA/Revenues | C42: =+C33 -> 0.31754234 | D42: =+D33 -> 0.33843301 | E42: =+E33 -> 0.32798768 | F42: Se asume constante al promedio.
...
