Workbook

Sheet Noticia
B1: Datos: S-1 Cardinal, Reuters & Nasdaq
B3: MVE | C3: 768000000 | D3: 805000000
B4: # Shares outstading (Class A & B) According S-1 | D4: 36610000
B5: Price per share | C5: 20 | D5: 22
B6: Looking to raise up to | C6: 253000000

Sheet Empresas comparables
B1: Empresa | C1: Ticker | D1: Descripción (Yahoo Finance para las comparables, S-1 Filing para CDNL) | E1: Comentario
B2: Cardinal Infrastructure Group Inc. | C2: CDNL | D2: We provide a comprehensive suite of infrastructure services to the residential, commercial, industrial, municipal, and state infrastructure markets. Our operations leverage a large highly skilled workforce and a fleet of specialized equipment to deliver wet utility installations (water, sewer, and stormwater systems), as well as grading, site clearing, erosion control, drilling and blasting, paving, and other related site services. We are becoming the platform of choice for a diverse array of infrastructure construction projects in our target geographies that require high-level technical expertise and sophistication. We seek to safely execute site work solutions within both the individual project’s schedule and budget, while strengthening our relationships with our growing list of customers. We believe we are one of the fastest-growing, full-service turnkey infrastructure services companies in the Southeastern United States. We deliver our suite of comprehensive infrastructure services that support the planning, preparation, installation, and development of residential, commercial, industrial, municipal, and state infrastructure projects primarily through in-house teams and equipment, significantly reducing the need for outsourcing or subcontractors which enables industry-leading project execution. Led by an experienced, long-tenured management team and supported by talented project managers, we are driven by a culture of safety and employee development. Our high-level expertise, technical sophistication, and expedited delivery of services result in strong margins. We believe we are well positioned to continue growing our revenue and profitability in a very fragmented and highly attractive industry. | E2: Es una empresa estadounidense que construye infraestructura principalmente en el sureste del país, con operaciones en Charlotte, Raleigh y Greensboro, Carolina del Norte. Ofrece servicios completos o “turnkey” para proyectos residenciales, comerciales e industriales, como instalación de sistemas de agua, alcantarillado y drenaje, además de preparación de terrenos: nivelación, limpieza, control de erosión, perforación, voladuras y pavimentación.
B3: Sterling Infrastructure, Inc. | C3: STRL | D3: Sterling Infrastructure, Inc. engages in the provision of e-infrastructure, transportation, and building solutions in the United States. It operates through three segments: E-Infrastructure Solutions, Transportation Solutions, and Building Solutions. The E-Infrastructure Solutions segment provides site development services for the blue-chip end users in the e-commerce distribution center, data center, manufacturing, warehousing, and power generation sectors. The Transportation Solutions segment is involved in the development of infrastructure and rehabilitation projects for highways, roads, bridges, airports, ports, rail, and storm drainage systems for the departments of transportation, regional transit, airport, port, water, and railroads authorities. The Building Solutions segment provides residential and commercial concrete foundations for single-family and multi-family homes, parking structures, elevated slabs, other concrete work for developers and general contractors, as well as provides plumbing and surveys services for residential builds. The company was formerly known as Sterling Construction Company, Inc. and changed its name to Sterling Infrastructure, Inc. in June 2022. Sterling Infrastructure, Inc. was founded in 1955 and is headquartered in The Woodlands, Texas. | E3: Es un proveedor de servicios de infraestructura que opera en 3 segmentos, de los 3, Transportación y Construcción, son los que se asemejan al modelo de preparación de terrenos de Cardinal.
B4: Granite Construction Incorporated | C4: GVA | D4: Granite Construction Incorporated operates as an infrastructure contractor in the United States. It operates through two segments: Construction and Materials segments. The Construction segment engages in the construction and rehabilitation of roads, pavement preservation, bridges, rail lines, airports, marine ports, dams, reservoirs, aqueducts, infrastructure, and site development for use by the public and water-related construction for municipal agencies, commercial water suppliers, industrial facilities, and energy companies; and construction of various complex projects, including infrastructure and site development, mining, public safety, tunnel, solar, battery storage, and power related projects. The Materials segment is involved in the production of aggregates, asphalt concrete, liquid asphalt, and recycled materials production for internal use in construction projects and sale to third parties. It also offers site preparation, mining, and infrastructure services for railways, residential development, energy development, and commercial and industrial sites; and provides construction management professional services. The company serves federal agencies, state departments of transportation, local transit authorities, county and city public works departments, school districts and developers, utilities, contractors, landscapers, manufacturers of products requiring aggregate materials, retailers, homeowners, farmers, brokers, and private owners of industrial, commercial, and residential sites. Granite Construction Incorporated was incorporated in 1922 and is headquartered in Watsonville, California. | E4: La similitud con Cardinal es el segmento de Construcción bajo el cual operan, que abarca rehabilitación de caminos, preservación del pavimento, puentes, entre otros, sin embargo, considerar que es una compañía de gran tamaño.
B5: Construction Partners, Inc. | C5: ROAD | D5: Construction Partners, Inc., a civil infrastructure company, constructs and maintains roadways in Alabama, Florida, Georgia, North Carolina, Oklahoma, South Carolina, Tennessee, and Texas. The company provides various products and services to public and private infrastructure projects, such as highways, roads, bridges, airports, and commercial and residential developments. It also engages in manufacturing and distributing hot mix asphalt (HMA) for internal use and sales to third parties in connection with construction projects; and paving activities, including the construction of roadway base layers and application of asphalt pavement. In addition, the company is involved in site development, including the installation of utility and drainage systems; mining aggregates, such as sand, gravel, and construction stones that are used as raw materials in the production of HMA; and distributing liquid asphalt cement for internal use and sales to third parties in connection with HMA production. The company was formerly known as SunTx CPI Growth Company, Inc. and changed its name to Construction Partners, Inc. in September 2017. Construction Partners, Inc. was incorporated in 2007 and is headquartered in Dothan, Alabama. | E5: Muy enfocada en pavimentación, carreteras y desarrollo de sitios en el sur/sureste de Estados Unidos.
B6: Primoris Services Corporation | C6: PRIM | D6: Primoris Services Corporation provides infrastructure services primarily in the United States and Canada. The company operates in two segments, Utilities and Energy. The Utilities segment offers installation and maintenance of new and existing natural gas and electric utility distribution and transmission systems, and communications systems. The Energy segment provides engineering, procurement, construction, and maintenance services for entities in the energy, renewable energy and energy storage, renewable fuels, and petroleum and petrochemical industries, as well as state departments of transportation. The company also offers replacement and fabrication services. Primoris Services Corporation was founded in 1960 and is headquartered in Dallas, Texas. | E6: Su segmento Utilities es más líneas de gas, eléctricas y comunicaciones a gran escala en todo Estados Unidos y Canadá, no tanto wet utilities residenciales.
B7: Quanta Services, Inc. | C7: PWR | D7: Quanta Services, Inc. offers infrastructure solutions for the electric and gas utility, renewable energy, communications, pipeline, and energy industries in the United States, Canada, Australia, and internationally. The company's Electric Power Infrastructure Solutions segment engages in the design, procurement, construction, upgrade, repair, and maintenance of electric power transmission and distribution infrastructure and substation facilities; installation, maintenance, and upgrade of electric power infrastructure projects; installation of smart grid technologies on electric power networks; and design, installation, maintenance, and repair of commercial and industrial wirings. This segment offers aviation; emergency restoration; and other engineering and technical services; design and construction solutions to wireline and wireless communications, cable multi-system operators, and other customers; and training for electric workers, as well as training for the gas distribution and communications industries. Its Renewable Energy Infrastructure Solutions segment is involved in engineering, procurement, construction, repair, and maintenance of wind, solar, and hydropower generation facilities, as well as battery storage facilities; and engineering and construction services for substations and switchyards, transmission, and other electrical infrastructures. The company's Underground Utility and Infrastructure Solutions segment offers design, engineering, procurement, construction, upgrade, repair, and maintenance services for natural gas systems for gas utility customers; fabrication services for pipeline support systems and structures and facilities; and engineering and construction services for pipeline and storage systems, and compressor and pump stations. The company was formerly known as Fabal Construction, Inc. and changed its name to Quanta Services, Inc. in November 1997. The company was incorporated in 1997 and is headquartered in Houston, Texas. | E7: Aunque opera en construcción de infraestructura, su foco está mucho más concentrado en redes eléctricas y energéticas a gran escala.
B8: MasTec, Inc. | C8: MTZ | D8: MasTec, Inc., an infrastructure construction company, provides engineering, building, installation, maintenance, and upgrade services for communications, energy, utility, and other infrastructure primarily in the United States and Canada. It operates through five segments: Communications, Clean Energy and Infrastructure, Power Delivery, Pipeline Infrastructure, and Other. The company build infrastructure for wireless and wireline/fiber communications; clean energy infrastructure comprising renewable energy power generation; pipeline infrastructure, including natural gas, water, carbon capture sequestration, and other product transport; power delivery services, such as electrical and gas transmission, and distribution systems; industrial and heavy civil infrastructure, including roads, bridges, and rail; and water infrastructure. It also installs electrical and other gas distribution and transmission systems, power generation, power generation, civil and industrial facilities, pipelines, and fiber optic and other cables, as well as install-to-the-home services. In addition, the company offers maintenance and upgrade support services comprising maintenance of customers' distribution facilities, networks, and infrastructure, including communications, power generation, pipeline, electrical distribution and transmission, and civil and industrial infrastructure; service restoration for natural disasters and accidents; and routine replacements and upgrades to overhauls. Its customers include wireless and wireline/fiber service providers, broadband operators, install-to-the-home service providers, public and private energy providers, including renewable and other energy providers, pipeline operators, civil, transportation, and industrial infrastructure providers, as well as government entities. MasTec, Inc. was founded in 1929 and is headquartered in Coral Gables, Florida. | E8: Si bien forma parte del mercado más amplio de construcción de infraestructura, su exposición a proyectos es de energía, petróleo y gas.
B9: EMCOR Group, Inc | C9: EME | D9: EMCOR Group, Inc. provides electrical and mechanical construction and facilities, building, and industrial services in the United States and the United Kingdom. It offers design, integration, installation, startup, operation, and maintenance services related to power transmission, distribution, and generation systems; energy solutions; premises electrical and lighting systems; process instrumentation; low-voltage systems; voice and data communications systems; roadway and transit lighting, signaling, and fiber optic lines; computerized traffic control systems, and signal and communication equipment; heating, ventilation, air conditioning, refrigeration, and geothermal solutions; clean-room process ventilation systems; fire protection and suppression systems; plumbing, process, and piping systems; control and filtration systems; water and wastewater treatment systems; central plant heating and cooling systems; crane and rigging; millwright; and steel fabrication, erection, and welding services. The company also provides site-based operations and maintenance; facility management and maintenance; energy retrofit; military base operations support; indoor air quality; floor care and janitorial; landscaping, lot sweeping, and snow removal; vendor management and call center; installation and support for building systems; program development, management, and maintenance for energy systems; technical consulting and diagnostic; infrastructure and building projects; modification and retrofit projects; and reception, security, and catering services. In addition, it offers refinery turnaround planning and engineering; welding; overhaul and maintenance; technical; instrumentation, controls, and electrical; electrical panel design, fabrication, and installation; on-site repair and maintenance; and renewable energy services, as well as design, manufacturing, repair, and hydro blast cleaning services. The company was incorporated in 1987 and is headquartered in Norwalk, Connecticut. | E9: Pese que participa en proyectos de infraestructura, su modelo de negocio está más orientado a servicios técnicos, mantenimiento de instalaciones y proyectos industriales.

Sheet BS
B1: CARDINAL CIVIL CONTRACTING, LLC
B2: CONSOLIDATED BALANCE SHEETS
B3: As of December 31, 2024 and December 31, 2023
H4: December 31,
H5: 2023 | I5: 2024
B6: Assets
B7: Cash and cash equivalents | H7: 7220616 | I7: 20917108 | M7: =+H18-H37 -> 0 | N7: =+I18-I37 -> 0
B8: Accounts receivable | H8: 34089899 | I8: 38304817
B9: Contract assets | H9: 18126751 | I9: 17700380
B10: Prepaid expenses | H10: 340160 | I10: 373442
B11: Other current assets | H11: 1538498 | I11: 89349
B12: Total current assets | H12: =SUM(H7:H11) -> 61315924 | I12: =SUM(I7:I11) -> 77385096
B13: Property and Equipment, net | H13: 43840783 | I13: 49784405
B14: Operating lease right-of-use assets | H14: 6190800 | I14: 5109316
B15: Investments in unconsolidated affiliates | H15: 369486 | I15: 984041
B16: Goodwill | H16: 7050963 | I16: 7050963
B17: Total non-current assets | H17: =SUM(H13:H16) -> 57452032 | I17: =SUM(I13:I16) -> 62928725
B18: Total assets | H18: =+H17+H12 -> 118767956 | I18: =+I17+I12 -> 140313821
B20: Liabilities and Partners' Equity
B21: Current portion of notes payable | H21: 12612255 | I21: 11112540
B22: Current portion of finance lease liabilities | H22: 2233141 | I22: 3075705
B23: Current portion of operating lease liabilities | H23: 2707054 | I23: 2801545
B24: Accounts payable | H24: 41279367 | I24: 38279318
B25: Accrued distributions | H25: 918826 | I25: 341736
B26: Accrued expenses | H26: 1443367 | I26: 792427
B27: Contract liabilities | H27: 12449842 | I27: 14143518
B28: Total current liabilities | H28: =SUM(H21:H27) -> 73643852 | I28: =SUM(I21:I27) -> 70546789
B29: Notes payable, less current portion, net of unamortized debt issuance costs | H29: 27592777 | I29: 36821209
B30: Finance lease liabilities, less current portion | H30: 6454214 | I30: 7161862
B31: Operating lease liabilities, less current portion | H31: 3607652 | I31: 2429985
B32: Total non-current liabilities | H32: =SUM(H29:H31) -> 37654643 | I32: =SUM(I29:I31) -> 46413056
B33: Total liabilities | H33: =+H32+H28 -> 111298495 | I33: =+I32+I28 -> 116959845
B34: Noncontrolling interests | H34: 7026140 | I34: 11596261
B35: Retained earnings | H35: 443321 | I35: 11757715
B36: Total members’ equity | H36: =SUM(H34:H35) -> 7469461 | I36: =SUM(I34:I35) -> 23353976
B37: Total liabilities and partners' equity | H37: =+H28+H32+H36 -> 118767956 | I37: =+I28+I32+I36 -> 140313821

Sheet IS
B1: CARDINAL CIVIL CONTRACTING, LLC
B2: CONSOLIDATED STATEMENTS OF OPERATIONS
B3: Years Ended December 31, 2024 and December 31, 2023
C6: For the Years Ended December 31,
C7: 2023 | D7: 2024
B9: Revenues | C9: 247924063 | D9: 315187523
B10: COGS | C10: 199080030 | D10: 249888575
B11: Gross Profit | C11: =+C9-C10 -> 48844033 | D11: =+D9-D10 -> 65298948
B12: General and admnistrative expenses | C12: 6498758 | D12: 10687302
B13: Depreciation expense | C13: 13181191 | D13: 18663746
B14: Loss (gain) on disposal of property and equipment | C14: -365919 | D14: 13534
B15: Total operating expenses | C15: =SUM(C12:C14) -> 19314030 | D15: =SUM(D12:D14) -> 29364582
B16: Operating income (EBIT) | C16: =+C11-C15 -> 29530003 | D16: =+D11-D15 -> 35934366
B17: Interest expense, net | C17: -3990288 | D17: -4828058
B18: Other expense, net | C18: -1242923 | D18: -1456565
B19: Total other income | C19: =SUM(C17:C18) -> -5233211 | D19: =SUM(D17:D18) -> -6284623
B20: EBT | C20: =+C16+C19 -> 24296792 | D20: =+D16+D19 -> 29649743
B21: Income tax expense | C21: 0 | D21: -1352509
B22: Net income, including noncontrolling interests | C22: =+C20+C21 -> 24296792 | D22: =+D20+D21 -> 28297234
B23: Less: Net income attributable to noncontrolling interests | C23: 3724472 | D23: 6939888
B24: Net income attributable to Cardinal Civil Contracting, LLC | C24: =+C22-C23 -> 20572320 | D24: =+D22-D23 -> 21357346

Sheet Análisis Financiero
H1: Dato atípico | I1: 2023 | J1: 2024
H2: Tau actual | I2: =+IS!C21/IS!C20 -> 0 | J2: =+IS!D21/IS!D20 -> -0.045616213 | M2: Datos obtenidos de Morningstar
B3: Ratios | D3: 2023 | E3: 2024 | I3: Growth Metrics (g) | K3: 2024 | M3: Competencia | N3: Pretax Income | O3: Tax Provision | P3: Tau
B4: Liquidity | I4: Revenues | K4: =+(IS!D9-IS!C9)/IS!C9 -> 0.2713067 | M4: STRL | N4: 358278000 | O4: 87360000 | P4: =+O4/N4 -> 0.243833
B5: Current Ratio | D5: =+BS!H12/BS!H28 -> 0.83260072 | E5: =+BS!I12/BS!I28 -> 1.0969329 | I5: SGA | K5: =+(IS!D15-IS!C15)/IS!C15 -> 0.52037571 | M5: GVA | N5: 196192000 | O5: 55749000 | P5: =+O5/N5 -> 0.28415532
B6: OWK | D6: =+BS!H7+BS!H8-BS!H24+((BS!H10+BS!H11+BS!H9)-(BS!H26+BS!H27)) -> 6143348 | E6: =+BS!I7+BS!I8-BS!I24+((BS!I10+BS!I11+BS!I9)-(BS!I26+BS!I27)) -> 24169833 | I6: Gross Margin | K6: =+((E10-D10)/D10) -> 0.051584877 | M6: ROAD | N6: 92099000 | O6: 23161000 | P6: =+O6/N6 -> 0.25147939
B7: Cambio en OWK | E7: =+E6-D6 -> 18026485 | I7: Operating Margin | K7: =+((E11-D11)/D11) -> -0.042814394
I8: Net Margin | K8: =+((E12-D12)/D12) -> -0.18339191
B9: Profitability | I9: SGA/Revenues | K9: =+((E23-D23))/D23 -> 0.29356239
B10: Gross Margin | D10: =+IS!C11/IS!C9 -> 0.19701207 | E10: =+IS!D11/IS!D9 -> 0.20717491 | I10: OWK/Revenues | K10: =+(E24-D24)/D24 -> 2.0946974
B11: Operating Margin | D11: =+IS!C16/IS!C9 -> 0.11910906 | E11: =+IS!D16/IS!D9 -> 0.11400948 | I11: IC/Revenues | K11: =+(E25-D25)/D25 -> 0.023144363
B12: Net Margin | D12: =+IS!C24/IS!C9 -> 0.082978311 | E12: =+IS!D24/IS!D9 -> 0.06776076 | M12: 2024 | O12: 2023
B13: ROE | E13: =+IS!D24/BS!I36 -> 0.91450578
B14: ROA | D14: =+IS!C24/BS!H18 -> 0.1732144 | E14: =+IS!D24/BS!I18 -> 0.15221128
B15: Tau normalizado | C15: 0.25 | M15: Competencia | N15: EBIT | O15: NOPAT | P15: BVD | Q15: BVE | R15: IC | S15: ROIC - 2024
B16: NOPAT = EBIT * (1-Tau(25%)) | D16: =+(1-$C$15)*IS!C16 -> 22147502 | E16: =+(1-$C$15)*IS!D16 -> 26950774 | M16: STRL | N16: 264622000 | O16: =N16*(1-P4) -> 2.0009842e+08 | P16: =19641000+314996000 -> 334637000 | Q16: 623853000 | R16: =+Q16+P16 -> 958490000 | S16: =+O16/R16 -> 0.20876423
B17: ROIC (Tau 25%) | E17: =+E16/D42 -> 0.42999771 | M17: GVA | N17: 207363000 | O17: =N17*(1-P5) -> 1.484397e+08 | P17: =614781000+39932000 -> 654713000 | Q17: 1026966000 | R17: =+P17+Q17 -> 1681679000 | S17: =+O17/R17 -> 0.088268749
B18: Tau 2024 | C18: =+ABS(J2) -> 0.045616213 | O18: =N18*(1-P6) -> 0
B19: NOPAT = EBIT * (1-Tau(25%)) | D19: =+(1-$C$18)*IS!D16 -> 34295176 | E19: =+(1-C18)*IS!D16 -> 34295176 | O19: =N19*(1-P7) -> 0
B20: ROIC (Tau 4.56%) | E20: =+E19/D42 -> 0.54717712 | O20: =N20*(1-P8) -> 0
M21: ROAD | N21: 111240000 | O21: =N21*(1-P9) -> 111240000 | P21: =360740000+15000000 -> 375740000 | Q21: 516574000 | R21: =+P21+Q21 -> 892314000 | S21: =+O21/R21 -> 0.12466464
B22: Operational Efficiency | M22: CNDL | N22: =+IS!D16 -> 35934366 | O22: =N22*(1-C15) -> 26950774 | P22: =+E45 -> 58171316 | Q22: =+E46 -> 23353976 | R22: =+D42 -> 62676554 | S22: =+O22/R22 -> 0.42999771
B23: SGA/Revenues | D23: =+IS!C12/IS!C9 -> 0.026212696 | E23: =+IS!D12/IS!D9 -> 0.033907757 | Q23: Promedio de la competencia (STRL, GVA & ROAD) | S23: =+AVERAGE(S16:S21) -> 0.14056587
B24: OWK/Revenues | D24: =+D6/IS!C9 -> 0.024779152 | E24: =+E6/IS!D9 -> 0.076683978 | M24: Datos de Morningstar y S-1
B25: IC/Revenues | D25: =+D42/IS!C9 -> 0.25280545 | E25: =+E42/IS!D9 -> 0.25865647
B26: COGS/Revenues | D26: =+IS!C10/IS!C9 -> 0.80298793 | E26: =+IS!D10/IS!D9 -> 0.79282509
B27: Depreciation/Revenues | D27: =+IS!C13/IS!C9 -> 0.053166243 | E27: =+IS!D13/IS!D9 -> 0.059214736
B28: PPE/Revenues | D28: =+BS!H13/IS!C9 -> 0.1768315 | E28: =+BS!I13/IS!D9 -> 0.1579517
B29: EBITDA/Revenues | D29: =+(IS!C16+IS!C13)/IS!C9 -> 0.17227531 | E29: =+(IS!D16+IS!D13)/IS!D9 -> 0.17322422
B30: EBIT/Revenues | D30: =+IS!C16/IS!C9 -> 0.11910906 | E30: =+IS!D16/IS!D9 -> 0.11400948
B32: Leverage
B33: BVD/BVE - D/E | D33: =+D45/D46 -> 7.3910411 | E33: =+E45/E46 -> 2.4908528
B34: Net debt | D34: =+D45-BS!H7 -> 47986477 | E34: =+E45-BS!I7 -> 37254208
B35: EBITDA | D35: =+IS!C16+IS!C13 -> 42711194 | E35: =+IS!D16+IS!D13 -> 54598112
B36: Net debt / EBITDA | D36: =+D34/D35 -> 1.1235105 | E36: =+E34/E35 -> 0.6823351
B38: Summarized Balance | H38: Pesos
B39: P, P & E | D39: 2023 | E39: 2024 | F39: Cambios | G39: g | H39: 2023 | I39: 2024
B40: OWK | D40: =+D45+D46-D41 -> 18835771 | E40: =+E45+E46-E41 -> 31740887 | F40: =+E40-D40 -> 12905116 | G40: =+(E40-D40)/D40 -> 0.68513872 | H40: =+D40/D42 -> 0.3005234 | I40: =+E40/E42 -> 0.38933791
B41: Fixed Assests | D41: =+BS!H13 -> 43840783 | E41: =+BS!I13 -> 49784405 | F41: =+E41-D41 -> 5943622 | G41: =+(E41-D41)/D41 -> 0.1355729 | H41: =+D41/D42 -> 0.6994766 | I41: =+E41/E42 -> 0.61066209
B42: Invested Capital | D42: =SUM(D40:D41) -> 62676554 | E42: =SUM(E40:E41) -> 81525292 | F42: =+E42-D42 -> 18848738 | G42: =+(E42-D42)/D42 -> 0.30073029 | H42: =SUM(H40:H41) -> 1 | I42: =SUM(I40:I41) -> 1
...

Sheet Análisis de comparabilidad
B2: Datos: Yahoo Finance & Morningstar
D4: Datos usados del 2024
D5: Empresa | E5: Cardinal Infraestructure Group Inc | F5: Sterling Infrastructure, Inc. | G5: Granite Construction Incorporated | H5: Construction Partners, Inc.
D6: Ticker | E6: CNDL | F6: STRL | G6: GVA | H6: ROAD | I6: Promedio
D7: Tamaño y crecimiento
D8: Revenues | E8: =+IS!D9 -> 315187523 | F8: =+E28 -> 2115756000 | G8: =+D37 -> 3509138000 | H8: =+D46 -> 1563548000 | I8: =+AVERAGE(E8:H8) -> 1.8759074e+09
D9: g (crecimiento) | E9: =+'Análisis Financiero'!K4 -> 0.2713067 | F9: =+F28 -> 0.072774003 | G9: =+H38 -> 0.14203944 | H9: =+H47 -> 0.16650656 | I9: =+AVERAGE(E9:H9) -> 0.16315668
D10: Utilidad neta | E10: =+IS!D24 -> 21357346 | F10: =+E29 -> 257461000 | G10: =+E38 -> 126346000 | H10: =+E47 -> 68935000 | I10: =+AVERAGE(E10:H10) -> 1.1852484e+08
D11: Eficiencia operativa
D12: SGA | E12: =+IS!D12 -> 10687302 | F12: =+E31 -> 118424000 | G12: =+E40 -> 334162000 | H12: =+E49 -> 147607000 | I12: =+AVERAGE(E12:H12) -> 1.5272008e+08
D13: SGA/Revenues | E13: =+'Análisis Financiero'!E23 -> 0.033907757 | F13: =+E32 -> 0.055972428 | G13: =+E41 -> 0.083382615 | H13: =+E50 -> 0.080929815 | I13: =+AVERAGE(E13:H13) -> 0.063548154
D14: OWK | E14: =+'Análisis Financiero'!E6 -> 24169833 | F14: 279922000 | G14: 684704000 | H14: 204552000 | I14: =+AVERAGE(E14:H14) -> 2.9833696e+08
D15: OWK/Revenues | E15: =+E14/E8 -> 0.076683978 | F15: =+F14/F8 -> 0.13230354 | G15: =+G14/G8 -> 0.19512028 | H15: =+H14/H8 -> 0.13082553 | I15: =+AVERAGE(E15:H15) -> 0.13373333
D16: IC | E16: =+'Análisis Financiero'!E42 -> 81525292 | F16: 1124402000 | G16: 1754274000 | H16: 1087264000 | I16: =+AVERAGE(E16:H16) -> 1011866323
D17: IC/Revenues | E17: =+E16/E8 -> 0.25865647 | F17: =+F16/F8 -> 0.53144219 | G17: =+G16/G8 -> 0.49991593 | H17: =+H16/H8 -> 0.69538255 | I17: =+AVERAGE(E17:H17) -> 0.49634929
D18: Rentabilidad
D19: Margen Bruto | E19: =+'Análisis Financiero'!E10 -> 0.20717491 | F19: =+H30 -> 0.2014046 | G19: =+H39 -> 0.14290366 | H19: =+H48 -> 0.14159524 | I19: =+AVERAGE(E19:H19) -> 0.1732696
D20: Margen Operativo | E20: =+'Análisis Financiero'!E11 -> 0.11400948 | F20: =+H31 -> 0.12527106 | G20: =+H40 -> 0.049555916 | H20: =+H49 -> 0.060665424 | I20: =+AVERAGE(E20:H20) -> 0.087375471
D21: Margen Neto | E21: =+'Análisis Financiero'!E12 -> 0.06776076 | F21: =+H32 -> 0.12168747 | G21: =+H41 -> 0.031526804 | H21: =+H50 -> 0.037795611 | I21: =+AVERAGE(E21:H21) -> 0.064692662
D22: Liquidez
D23: Current Ratio | E23: =+'Análisis Financiero'!E5 -> 1.0969329 | F23: =+E34 -> 1.3772747 | G23: =+E43 -> 1.6634992 | H23: =+E52 -> 1.5376524 | I23: =+AVERAGE(E23:H23) -> 1.4188398
B27: STRL | D27: 2023 | E27: 2024 | F27: g | G27: STRL | K27: 2023 | L27: 2024
B28: Revenues | D28: 1972229000 | E28: 2115756000 | F28: =+(E28-D28)/D28 -> 0.072774003 | G28: Revenues | H28: =+E28 -> 2115756000 | J28: Total current assets | K28: 847979000 | L28: 1021880000
B29: Utilidad neta | D29: 138655000 | E29: 257461000 | F29: =+(E29-D29)/D29 -> 0.85684613 | G29: g | H29: =+F28 -> 0.072774003 | J29: Total current liabilities | K29: 678168000 | L29: 741958000
B30: Gross Profit | D30: 337638000 | E30: 426123000 | F30: =+(E30-D30)/D30 -> 0.26207062 | G30: Margen Bruto | H30: =+E30/E28 -> 0.2014046
B31: SGA | D31: 98703000 | E31: 118424000 | F31: =+(E31-D31)/D31 -> 0.19980142 | G31: Margen Operativo | H31: =+E33/E28 -> 0.12527106
B32: SGA/Revenues | D32: =+D31/D28 -> 0.05004642 | E32: =+E31/E28 -> 0.055972428 | F32: =+(E32-D32)/D32 -> 0.11841023 | G32: Margen Neto | H32: =+E29/E28 -> 0.12168747
B33: Operating Income | D33: 206668000 | E33: 265043000 | F33: =+(E33-D33)/D33 -> 0.28245786
B34: Current Ratio | D34: =+K28/K29 -> 1.2503967 | E34: =+L28/L29 -> 1.3772747 | F34: =+(E34-D34)/D34 -> 0.10147025
B36: GVA | D36: 2023 | E36: 2024 | F36: g | G36: GVA | K36: 2023 | L36: 2024
B37: Revenues | D37: 3509138000 | E37: 4007574000 | F37: =+(E37-D37)/D37 -> 0.14203944 | G37: Revenues | H37: =+E37 -> 4007574000 | J37: Total current assets | K37: 1643451000 | L37: 1716663000
B38: Utilidad neta | D38: 43599000 | E38: 126346000 | F38: =+(E38-D38)/D38 -> 1.8979105 | G38: g | H38: =+F37 -> 0.14203944 | J38: Total current liabilities | K38: 1029883000 | L38: 1031959000
B39: Gross Profit | D39: 396399000 | E39: 572697000 | F39: =+(E39-D39)/D39 -> 0.44474885 | G39: Margen Bruto | H39: =+E39/E37 -> 0.14290366
B40: SGA | D40: 294466000 | E40: 334162000 | F40: =+(E40-D40)/D40 -> 0.13480673 | G40: Margen Operativo | H40: =+E42/E37 -> 0.049555916
B41: SGA/Revenues | D41: =+D40/D37 -> 0.083914055 | E41: =+E40/E37 -> 0.083382615 | F41: =+(E41-D41)/D41 -> -0.0063331492 | G41: Margen Neto | H41: =+E38/E37 -> 0.031526804
B42: Operating Income | D42: 51716000 | E42: 198599000 | F42: =+(E42-D42)/D42 -> 2.8401849
B43: Current Ratio | D43: =+K37/K38 -> 1.5957648 | E43: =+L37/L38 -> 1.6634992 | F43: =+(E43-D43)/D43 -> 0.042446398
B45: ROAD | D45: FY 2023 - fiscal closing: september 30 | E45: FY 2024 - fiscal closing: september 30 | F45: g | G45: ROAD | K45: 2023 | L45: 2024
B46: Revenues | D46: 1563548000 | E46: 1823889000 | F46: =+(E46-D46)/D46 -> 0.16650656 | G46: Revenues | H46: =+E46 -> 1823889000 | J46: Total current assets | K46: 473424000 | L46: 585006000
B47: Utilidad neta | D47: 49001000 | E47: 68935000 | F47: =+(E47-D47)/D47 -> 0.40680802 | G47: g | H47: =+F46 -> 0.16650656 | J47: Total current liabilities | K47: 279183000 | L47: 380454000
...

Sheet Valoración por mútiplos
B2: Datos: Morningstar & Yahoo Finance
B4: Múltiplos para valoración
B5: Empresa | C5: STRL | D5: GVA | E5: ROAD | F5: Mínimo múltiplo | G5: Mediana | H5: Máximo múltiplo | I5: Max/min
B6: EV/EBITDA | C6: 15.2 | D6: 14.51 | E6: 26.56 | F6: =+MIN(C6:E6) -> 14.51 | G6: =+MEDIAN(C6:E6) -> 15.2 | H6: =+MAX(C6:E6) -> 26.56 | I6: =+MAX(C6:E6)/MIN(C6:E6) -> 1.8304618
B7: EV/EBIT | C7: 19.05 | D7: 25.07 | E7: 48.77 | F7: =+MIN(C7:E7) -> 19.05 | G7: =+MEDIAN(C7:E7) -> 25.07 | H7: =+MAX(C7:E7) -> 48.77 | I7: =+MAX(C7:E7)/MIN(C7:E7) -> 2.560105
B8: EV/Revenues | C8: 2.33 | D8: 1.01 | E8: 2.35 | F8: =+MIN(C8:E8) -> 1.01 | G8: =+MEDIAN(C8:E8) -> 2.33 | H8: =+MAX(C8:E8) -> 2.35 | I8: =+MAX(C8:E8)/MIN(C8:E8) -> 2.3267327
B11: Cardinal Infraestructure Group Inc | C11: EV con múltiplo mínimo | D11: EV con múltiplo medio | E11: EV con múltiplo máximo | G11: Cardinal | H11: 2024
B12: EV Valoración por EBITDA = (EBITDA*Múltiplo) | C12: =+(F6*$H$12) -> 7.9221861e+08 | D12: =+(G6*$H$12) -> 8.298913e+08 | E12: =+(H6*$H$12) -> 1.4501259e+09 | G12: EBITDA | H12: =+'Análisis Financiero'!E35 -> 54598112
B13: EV Valoración por EBIT = (EBIT*Múltiplo) | C13: =+(F7*$H$13) -> 6.8454967e+08 | D13: =+(G7*$H$13) -> 9.0087456e+08 | E13: =+(H7*$H$13) -> 1.752519e+09 | G13: EBIT | H13: =+IS!D16 -> 35934366
B14: EV Valoración por Revenues = (Revenues*Múltiplo) | C14: =+(F8*$H$14) -> 3.183394e+08 | D14: =+(G8*$H$14) -> 7.3438693e+08 | E14: =+(H8*$H$14) -> 7.4069068e+08 | G14: Revenues | H14: =+IS!D9 -> 315187523
B15: MVE Valoración por EBITDA = (EBITDA*Múltiplo)-BVD | C15: =+C12-'Análisis Financiero'!E45 -> 7.3404729e+08 | D15: =+D12-'Análisis Financiero'!E45 -> 7.7171999e+08 | E15: =+E12-'Análisis Financiero'!E45 -> 1.3919545e+09
B16: MVE Valoración por EBIT = (EBIT*Múltiplo)-BVD | C16: =+C13-'Análisis Financiero'!E45 -> 6.2637836e+08 | D16: =+D13-'Análisis Financiero'!E45 -> 8.4270324e+08 | E16: =+E13-'Análisis Financiero'!E45 -> 1.6943477e+09
B17: MVE Valoración por Revenues = (Revenues*Múltiplo)-BVD | C17: =+C14-'Análisis Financiero'!E45 -> 2.6016808e+08 | D17: =+D14-'Análisis Financiero'!E45 -> 6.7621561e+08 | E17: =+E14-'Análisis Financiero'!E45 -> 6.8251936e+08
B19: Precio por la acción EV/EBITDA | C19: =+C15/Noticia!$D$4 -> 20.050459 | D19: =+D15/Noticia!$D$4 -> 21.079486 | E19: =+E15/Noticia!$D$4 -> 38.021156
B20: Precio por la acción EV/EBIT | C20: =+C16/Noticia!$D$4 -> 17.109488 | D20: =+D16/Noticia!$D$4 -> 23.01839 | E20: =+E16/Noticia!$D$4 -> 46.281008
B21: Precio por la acción EV/Revenues | C21: =+C17/Noticia!$D$4 -> 7.1064759 | D21: =+D17/Noticia!$D$4 -> 18.47079 | E21: =+E17/Noticia!$D$4 -> 18.642976

Sheet WACC
B2: Datos: Morningstar, FRED, Aswath Damodaran & Yahoo Finance
B4: Ticker | C4: STRL | D4: GVA | E4: ROAD
B5: Currency | C5: USD | D5: USD | E5: USD
B6: Market | C6: XNAS | D6: XNYS | E6: XNAS
B7: Precio de acción (Previous close - 12/04/2025) | C7: 332.29 | D7: 108.31 | E7: 105.38
B8: Shares Outstanding | C8: 30720000 | D8: 43650000 | E8: 56530000
B9: Net Debt | C9: 369274000 | D9: 832851000 | E9: 553250000
B10: MVE | C10: =+C7*C8 -> 10207948800 | D10: =+D7*D8 -> 4727731500 | E10: =+E7*E8 -> 5957131400
B11: EV | C11: =+C10+C9 -> 10577222800 | D11: =+D10+D9 -> 5560582500 | E11: =+E10+E9 -> 6510381400
B12: Pretax Income | C12: =+'Análisis Financiero'!N4 -> 358278000 | D12: =+'Análisis Financiero'!N5 -> 196192000 | E12: =+'Análisis Financiero'!N6 -> 92099000
B13: Tax Provision | C13: =+'Análisis Financiero'!O4 -> 87360000 | D13: =+'Análisis Financiero'!O5 -> 55749000 | E13: =+'Análisis Financiero'!O6 -> 23161000
B14: rf | C14: 0.0411 | D14: 0.0411 | E14: 0.0411
B15: MRP | C15: 0.055 | D15: 0.055 | E15: 0.055
B16: Be (5Y Monthly Yahoo Finance) | C16: 1.49 | D16: 1.34 | E16: 0.88
B17: Tau | C17: =+C13/C12 -> 0.243833 | D17: =+D13/D12 -> 0.28415532 | E17: =+E13/E12 -> 0.25147939
B18: 1-Tau | C18: =1-C17 -> 0.756167 | D18: =1-D17 -> 0.71584468 | E18: =1-E17 -> 0.74852061
B19: rd | C19: 0.06 | D19: 0.06 | E19: 0.06 | F19: ROAD tiene un Debt Rating B+, basados en ese rating, se utiliza un 6%.
B20: rd-rf | C20: =+C19-C14 -> 0.0189 | D20: =+D19-D14 -> 0.0189 | E20: =+E19-E14 -> 0.0189
B21: Bd | C21: =+C20/C15 -> 0.34363636 | D21: =+D20/D15 -> 0.34363636 | E21: =+E20/E15 -> 0.34363636
B22: BVD - Deuda con costo = D | C22: =+C9 -> 369274000 | D22: =+D9 -> 832851000 | E22: =+E9 -> 553250000
B23: V=D+E | C23: =+C22+C10 -> 10577222800 | D23: =+D22+D10 -> 5560582500 | E23: =+E22+E10 -> 6510381400
B24: D/V | C24: =+C22/C23 -> 0.034912189 | D24: =+D22/D23 -> 0.14977765 | E24: =+E22/E23 -> 0.08497966 | F24: D/V promedio | G24: =+AVERAGE(C24:E24) -> 0.089889834
B25: E/V | C25: =+C10/C23 -> 0.96508781 | D25: =+D10/D23 -> 0.85022235 | E25: =+E10/E23 -> 0.91502034 | F25: E/V promedio | G25: =+AVERAGE(C25:E25) -> 0.91011017
B26: D/EV | C26: =+C22/C11 -> 0.034912189 | D26: =+D22/D11 -> 0.14977765 | E26: =+E22/E11 -> 0.08497966
B27: E/EV | C27: =+C10/C11 -> 0.96508781 | D27: =+D10/D11 -> 0.85022235 | E27: =+E10/E11 -> 0.91502034
B28: D(1-tau)/EV | C28: =+C9*(1-WACC!C17)/WACC!C11 -> 0.026399445 | D28: =+D9*(1-WACC!D17)/WACC!D11 -> 0.10721754 | E28: =+E9*(1-WACC!E17)/WACC!E11 -> 0.063609028
B29: re | C29: =+C14+C16*C15 -> 0.12305 | D29: =+D14+D16*D15 -> 0.1148 | E29: =+E14+E16*E15 -> 0.0895
B30: WACC (Current D/EV) | C30: =+C25*C29+C24*C18*C19 -> 0.12033802 | D30: =+D25*D29+D24*D18*D19 -> 0.10403858 | E30: =+E25*E29+E24*E18*E19 -> 0.085710862
B31: ra desapalancado | C31: =+C25*C29+C26*C19 -> 0.12084879 | D31: =+D25*D29+D26*D19 -> 0.10659218 | E31: =+E25*E29+E26*E19 -> 0.0869931
B32: Ba desapalacanda | C32: =+(C31-C14)/C15 -> 1.4499779 | D32: =+(D31-D14)/D15 -> 1.190767 | E32: =+(E31-E14)/E15 -> 0.83442 | F32: Ba promedio | G32: =+AVERAGE(C32:E32) -> 1.1583883
B33: Be apalancada | C33: =+C32+C18*C24*(C32-C21) -> 1.4791847 | D33: =+D32+D18*D24*(D32-D21) -> 1.2815943 | E33: =+E32+E18*E24*(E32-E21) -> 0.86563827
B34: WACC histórico sector | C34: =+C31-C17*C19*C24 -> 0.12033802 | D34: =+D31-D17*D19*D24 -> 0.10403858 | E34: =+E31-E17*E19*E24 -> 0.085710862
B36: Cardinal Infraestructure Group Inc (con D/EV calculado) | F36: Cardinal Infraestructure Group Inc (con estructura de capital media de la industria)
B37: rf (bono de tesoro de 10 años) | C37: 0.0411 | F37: rf (bono de tesoro de 10 años) | G37: 0.0411
B38: MRP | C38: 0.055 | F38: MRP | G38: 0.055
B39: Tau | C39: =+'Análisis Financiero'!C15 -> 0.25 | F39: D/V | G39: =+MEDIAN(C24:E24) -> 0.08497966
B40: Tau | C40: =+'Análisis Financiero'!C18 -> 0.045616213 | F40: E/V | G40: =+MEDIAN(C25:E25) -> 0.91502034
B41: D/E | C41: =+'Análisis Financiero'!E45/'Análisis Financiero'!E46 -> 2.4908528 | F41: Tau | G41: =+C39 -> 0.25
B42: V = D (BVD) + E (Total members'e Equity) | C42: =+'Análisis Financiero'!E45+'Análisis Financiero'!E46 -> 81525292 | F42: Ba apalancada | G42: =+MEDIAN(C32:E32) -> 1.190767
B43: D/V | C43: =+'Análisis Financiero'!E45/WACC!C42 -> 0.71353705 | F43: ra desapalancada | G43: =+G37+G42*G38 -> 0.10659218
...

Sheet Supuestos DCF - Perpetuo
B2: Datos usados del 2024
B3: Empresa | C3: Sterling Infrastructure, Inc. | D3: Granite Construction Incorporated | E3: Construction Partners, Inc.
B4: Ticker | C4: STRL | D4: GVA | E4: ROAD | F4: Promedio
B5: Tamaño y crecimiento
B6: Revenues | C6: =+'Análisis de comparabilidad'!F8 -> 2115756000 | D6: =+'Análisis de comparabilidad'!G8 -> 3509138000 | E6: =+'Análisis de comparabilidad'!H8 -> 1563548000 | F6: =+AVERAGE(C6:E6) -> 2.3961473e+09
B7: g (crecimiento) | C7: =+'Análisis de comparabilidad'!F9 -> 0.072774003 | D7: =+'Análisis de comparabilidad'!G9 -> 0.14203944 | E7: =+'Análisis de comparabilidad'!H9 -> 0.16650656 | F7: =+AVERAGE(C7:E7) -> 0.12710667
B8: Utilidad neta | C8: =+'Análisis de comparabilidad'!F10 -> 257461000 | D8: =+'Análisis de comparabilidad'!G10 -> 126346000 | E8: =+'Análisis de comparabilidad'!H10 -> 68935000 | F8: =+AVERAGE(C8:E8) -> 150914000
B9: Eficiencia operativa
B10: SGA | C10: =+'Análisis de comparabilidad'!F12 -> 118424000 | D10: =+'Análisis de comparabilidad'!G12 -> 334162000 | E10: =+'Análisis de comparabilidad'!H12 -> 147607000 | F10: =+AVERAGE(C10:E10) -> 2.0006433e+08
B11: SGA/Revenues | C11: =+'Análisis de comparabilidad'!F13 -> 0.055972428 | D11: =+'Análisis de comparabilidad'!G13 -> 0.083382615 | E11: =+'Análisis de comparabilidad'!H13 -> 0.080929815 | F11: =+AVERAGE(C11:E11) -> 0.073428286
B12: COGS | C12: 1689633000 | D12: 3434877000 | E12: 1565635000 | F12: =+AVERAGE(C12:E12) -> 2.2300483e+09
B13: COGS/Revenues | C13: =+C12/C6 -> 0.7985954 | D13: =+D12/D6 -> 0.97883782 | E13: =+E12/E6 -> 1.0013348 | F13: =+AVERAGE(C13:E13) -> 0.926256
B14: OWK | C14: =+'Análisis de comparabilidad'!F14 -> 279922000 | D14: =+'Análisis de comparabilidad'!G14 -> 684704000 | E14: =+'Análisis de comparabilidad'!H14 -> 204552000 | F14: =+AVERAGE(C14:E14) -> 389726000
B15: OWK/Revenues | C15: =+C14/C6 -> 0.13230354 | D15: =+D14/D6 -> 0.19512028 | E15: =+E14/E6 -> 0.13082553 | F15: =+AVERAGE(C15:E15) -> 0.15274978
B16: IC | C16: =+'Análisis de comparabilidad'!F16 -> 1124402000 | D16: =+'Análisis de comparabilidad'!G16 -> 1754274000 | E16: =+'Análisis de comparabilidad'!H16 -> 1087264000 | F16: =+AVERAGE(C16:E16) -> 1321980000
B17: IC/Revenues | C17: =+C16/C6 -> 0.53144219 | D17: =+D16/D6 -> 0.49991593 | E17: =+E16/E6 -> 0.69538255 | F17: =+AVERAGE(C17:E17) -> 0.57558023
B18: Rentabilidad
B19: Margen Bruto | C19: =+'Análisis de comparabilidad'!F19 -> 0.2014046 | D19: =+'Análisis de comparabilidad'!G19 -> 0.14290366 | E19: =+'Análisis de comparabilidad'!H19 -> 0.14159524 | F19: =+AVERAGE(C19:E19) -> 0.16196784
B20: Margen Operativo | C20: =+'Análisis de comparabilidad'!F20 -> 0.12527106 | D20: =+'Análisis de comparabilidad'!G20 -> 0.049555916 | E20: =+'Análisis de comparabilidad'!H20 -> 0.060665424 | F20: =+AVERAGE(C20:E20) -> 0.078497467
B21: Margen Neto | C21: =+'Análisis de comparabilidad'!F21 -> 0.12168747 | D21: =+'Análisis de comparabilidad'!G21 -> 0.031526804 | E21: =+'Análisis de comparabilidad'!H21 -> 0.037795611 | F21: =+AVERAGE(C21:E21) -> 0.063669963
B22: Liquidez
B23: Current Ratio | C23: =+'Análisis de comparabilidad'!E23 -> 1.0969329 | D23: =+'Análisis de comparabilidad'!F23 -> 1.3772747 | E23: =+'Análisis de comparabilidad'!G23 -> 1.6634992 | F23: =+'Análisis de comparabilidad'!H23 -> 1.5376524
B25: Cardinal - DCF Perpetuo. Se usan porcentajes de crecimiento en relación al PIB del 3%.
F26: Comentario
B27: Tau | C27: 0.25 | F27: Se asume constante
B28: Caso Pesimista
C29: 2023 | D29: 2024 | E29: Promedio | F29: Comentario
B30: Revenues | C30: =+IS!C9 -> 247924063 | D30: =+IS!D9 -> 315187523 | E30: =+AVERAGE(C30:D30) -> 281555793 | F30: Crece hasta llegar a un 2% en el último año, determinando el peor caso posible.
B31: EBIT/Revenues | C31: =+'Análisis Financiero'!D30 -> 0.11910906 | D31: =+'Análisis Financiero'!E30 -> 0.11400948 | E31: =+AVERAGE(C31:D31) -> 0.11655927 | F31: Se asume constante al promedio.
B32: SGA/Revenues | C32: =+'Análisis Financiero'!D23 -> 0.026212696 | D32: =+'Análisis Financiero'!E23 -> 0.033907757 | E32: =+AVERAGE(C32:D32) -> 0.030060226 | F32: Se asume constante al promedio.
B33: OWK/Revenues | C33: =+'Análisis Financiero'!D24 -> 0.024779152 | D33: =+'Análisis Financiero'!E24 -> 0.076683978 | E33: =+AVERAGE(C33:D33) -> 0.050731565 | F33: Se asume que aumenta al 6%, por el tema de expansión y adquicisiones.
B34: PPE/Revenues | C34: =+'Análisis Financiero'!D28 -> 0.1768315 | D34: =+'Análisis Financiero'!E28 -> 0.1579517 | E34: =+AVERAGE(C34:D34) -> 0.1673916 | F34: Se asume un incremento al 18%, dado a si falla su modelo de expansión, requiriendo mayor inversión en activos para sostener crecimiento.
B35: Caso Base
C36: 2023 | D36: 2024 | E36: Promedio | F36: Comentario
B37: Revenues | C37: =+C30 -> 247924063 | D37: =+D30 -> 315187523 | E37: =+E30 -> 281555793 | F37: Crece hasta llegar a un 3% en el último año, estableciendo un crecimiento por debajo del CAGR proyecto a 10 años, pero en paralelo al crecimiento de la economía.
B38: EBIT/Revenues | C38: =+C31 -> 0.11910906 | D38: =+'Análisis Financiero'!E30 -> 0.11400948 | E38: =+E31 -> 0.11655927 | F38: Se asume constante al promedio.
B39: SGA/Revenues | C39: =+C32 -> 0.026212696 | D39: =+D32 -> 0.033907757 | E39: =+E32 -> 0.030060226 | F39: Se asume constante al promedio.
B40: OWK/Revenues | C40: =+C33 -> 0.024779152 | D40: =+D33 -> 0.076683978 | E40: =+E33 -> 0.050731565 | F40: Se asume constante al promedio.
B41: PPE/Revenues | C41: =+C34 -> 0.1768315 | D41: =+D34 -> 0.1579517 | E41: =+E34 -> 0.1673916 | F41: Se asume constante al promedio.
B42: Caso Optimista
...

Sheet Supuestos DCF - Múltiplo
B2: Datos usados del 2024
B3: Empresa | C3: Sterling Infrastructure, Inc. | D3: Granite Construction Incorporated | E3: Construction Partners, Inc.
B4: Ticker | C4: STRL | D4: GVA | E4: ROAD | F4: Promedio
B5: Tamaño y crecimiento
B6: Revenues | C6: =+'Análisis de comparabilidad'!F8 -> 2115756000 | D6: =+'Análisis de comparabilidad'!G8 -> 3509138000 | E6: =+'Análisis de comparabilidad'!H8 -> 1563548000 | F6: =+AVERAGE(C6:E6) -> 2.3961473e+09
B7: g (crecimiento) | C7: =+'Análisis de comparabilidad'!F9 -> 0.072774003 | D7: =+'Análisis de comparabilidad'!G9 -> 0.14203944 | E7: =+'Análisis de comparabilidad'!H9 -> 0.16650656 | F7: =+AVERAGE(C7:E7) -> 0.12710667
B8: Utilidad neta | C8: =+'Análisis de comparabilidad'!F10 -> 257461000 | D8: =+'Análisis de comparabilidad'!G10 -> 126346000 | E8: =+'Análisis de comparabilidad'!H10 -> 68935000 | F8: =+AVERAGE(C8:E8) -> 150914000
B9: Eficiencia operativa
B10: SGA | C10: =+'Análisis de comparabilidad'!F12 -> 118424000 | D10: =+'Análisis de comparabilidad'!G12 -> 334162000 | E10: =+'Análisis de comparabilidad'!H12 -> 147607000 | F10: =+AVERAGE(C10:E10) -> 2.0006433e+08
B11: SGA/Revenues | C11: =+'Análisis de comparabilidad'!F13 -> 0.055972428 | D11: =+'Análisis de comparabilidad'!G13 -> 0.083382615 | E11: =+'Análisis de comparabilidad'!H13 -> 0.080929815 | F11: =+AVERAGE(C11:E11) -> 0.073428286
B12: COGS | C12: 1689633000 | D12: 3434877000 | E12: 1565635000 | F12: =+AVERAGE(C12:E12) -> 2.2300483e+09
B13: COGS/Revenues | C13: =+C12/C6 -> 0.7985954 | D13: =+D12/D6 -> 0.97883782 | E13: =+E12/E6 -> 1.0013348 | F13: =+AVERAGE(C13:E13) -> 0.926256
B14: OWK | C14: =+'Análisis de comparabilidad'!F14 -> 279922000 | D14: =+'Análisis de comparabilidad'!G14 -> 684704000 | E14: =+'Análisis de comparabilidad'!H14 -> 204552000 | F14: =+AVERAGE(C14:E14) -> 389726000
B15: OWK/Revenues | C15: =+C14/C6 -> 0.13230354 | D15: =+D14/D6 -> 0.19512028 | E15: =+E14/E6 -> 0.13082553 | F15: =+AVERAGE(C15:E15) -> 0.15274978
B16: IC | C16: =+'Análisis de comparabilidad'!F16 -> 1124402000 | D16: =+'Análisis de comparabilidad'!G16 -> 1754274000 | E16: =+'Análisis de comparabilidad'!H16 -> 1087264000 | F16: =+AVERAGE(C16:E16) -> 1321980000
B17: IC/Revenues | C17: =+C16/C6 -> 0.53144219 | D17: =+D16/D6 -> 0.49991593 | E17: =+E16/E6 -> 0.69538255 | F17: =+AVERAGE(C17:E17) -> 0.57558023
B18: Rentabilidad
B19: Margen Bruto | C19: =+'Análisis de comparabilidad'!F19 -> 0.2014046 | D19: =+'Análisis de comparabilidad'!G19 -> 0.14290366 | E19: =+'Análisis de comparabilidad'!H19 -> 0.14159524 | F19: =+AVERAGE(C19:E19) -> 0.16196784
B20: Margen Operativo | C20: =+'Análisis de comparabilidad'!F20 -> 0.12527106 | D20: =+'Análisis de comparabilidad'!G20 -> 0.049555916 | E20: =+'Análisis de comparabilidad'!H20 -> 0.060665424 | F20: =+AVERAGE(C20:E20) -> 0.078497467
B21: Margen Neto | C21: =+'Análisis de comparabilidad'!F21 -> 0.12168747 | D21: =+'Análisis de comparabilidad'!G21 -> 0.031526804 | E21: =+'Análisis de comparabilidad'!H21 -> 0.037795611 | F21: =+AVERAGE(C21:E21) -> 0.063669963
B22: Liquidez
B23: Current Ratio | C23: =+'Análisis de comparabilidad'!E23 -> 1.0969329 | D23: =+'Análisis de comparabilidad'!F23 -> 1.3772747 | E23: =+'Análisis de comparabilidad'!G23 -> 1.6634992 | F23: =+'Análisis de comparabilidad'!H23 -> 1.5376524
B25: Cardinal
F26: Comentario
B27: Tau | C27: 0.25 | F27: Se asume constante
B28: Caso Pesimista
C29: 2023 | D29: 2024 | E29: Promedio | F29: Comentario
B30: Revenues | C30: =+IS!C9 -> 247924063 | D30: =+IS!D9 -> 315187523 | E30: =+AVERAGE(C30:D30) -> 281555793 | F30: Crece de igual forma que el base, pero disminuye a un 3% en el último año, determinando el peor caso posible.
B31: EBIT/Revenues | C31: =+'Análisis Financiero'!D30 -> 0.11910906 | D31: =+'Análisis Financiero'!E30 -> 0.11400948 | E31: =+AVERAGE(C31:D31) -> 0.11655927 | F31: Se asume que baja un 1% en referencia a al promedio de la industria.
B32: EBITDA/Revenues | C32: =+'Análisis Financiero'!D29 -> 0.17227531 | D32: =+'Análisis Financiero'!E29 -> 0.17322422 | E32: =+AVERAGE(C32:D32) -> 0.17274976 | F32: Se asume que baja un 4% en referencia a al promedio de la industria.
B33: SGA/Revenues | C33: =+'Análisis Financiero'!D23 -> 0.026212696 | D33: =+'Análisis Financiero'!E23 -> 0.033907757 | E33: =+AVERAGE(C33:D33) -> 0.030060226 | F33: Se asume constante al promedio.
B34: D/Revenues | C34: =+'Análisis Financiero'!D27 -> 0.053166243 | D34: =+'Análisis Financiero'!E27 -> 0.059214736 | E34: =+AVERAGE(C34:D34) -> 0.05619049 | F34: Se asume constante al promedio.
B35: OWK/Revenues | C35: =+'Análisis Financiero'!D24 -> 0.024779152 | D35: =+'Análisis Financiero'!E24 -> 0.076683978 | E35: =+AVERAGE(C35:D35) -> 0.050731565 | F35: Se asume que aumenta al 10%, por el tema de expansión y adquicisiones.
B36: PPE/Revenues | C36: =+'Análisis Financiero'!D28 -> 0.1768315 | D36: =+'Análisis Financiero'!E28 -> 0.1579517 | E36: =+AVERAGE(C36:D36) -> 0.1673916 | F36: Se asume un incremento al 18%, dado a si falla su modelo de expansión, requiriendo mayor inversión en activos para sostener crecimiento.
B37: Caso Base
C38: 2023 | D38: 2024 | E38: Promedio | F38: Comentario
B39: Revenues | C39: =+C30 -> 247924063 | D39: =+D30 -> 315187523 | E39: =+E30 -> 281555793 | F39: Se determina a un 27.13% y baja en relación a su aumento, en un 5% cada año, cercano al 6.3% de incremento de población que espera Cardinal y a su vez, similar al 5.3% del CAGR de la industria pronosticado hasta el 2035.
B40: EBIT/Revenues | C40: =+C31 -> 0.11910906 | D40: =+'Análisis Financiero'!E30 -> 0.11400948 | E40: =+E31 -> 0.11655927 | F40: Se asume que baja un 2% en referencia a al promedio de la industria.
B41: EBITDA/Revenues | C41: =+C32 -> 0.17227531 | D41: =+D32 -> 0.17322422 | E41: =+E32 -> 0.17274976 | F41: Se asume que baja un 2% en referencia a al promedio de la industria.
B42: SGA/Revenues | C42: =+C33 -> 0.026212696 | D42: =+D33 -> 0.033907757 | E42: =+E33 -> 0.030060226 | F42: Se asume constante al promedio.
...

Sheet DCF Pesismista - Perpetuo
B1: DCF Pesimista
B2: Supuestos generales
B3: k (WACC Meta) | C3: =+WACC!G44 -> 0.10432764
B4: g terminal | C4: 0.02
B5: Tau | C5: =+'Análisis Financiero'!C15 -> 0.25
B6: Supuestos operativos | C6: 2023 | D6: 2024 | E6: Promedio | F6: Se asume
B7: EBIT/Revenues | C7: =+C17 -> 0.11910906 | D7: =+D17 -> 0.11400948 | E7: =+AVERAGE(C7:D7) -> 0.11655927 | F7: =+E7 -> 0.11655927
B8: OWK/Revenues | C8: =+C21 -> 0.024779152 | D8: =+D21 -> 0.076683978 | E8: =+AVERAGE(C8:D8) -> 0.050731565 | F8: =+E8+0.93% -> 0.060031565
B9: PPE/Revenues | C9: =+C23 -> 0.1768315 | D9: =+D23 -> 0.1579517 | E9: =+AVERAGE(C9:D9) -> 0.1673916 | F9: =+E9+0.26% -> 0.1699916
B11: Tasa promedio de convergencia al crecimiento de largo plazo
B12: =+(D15-C4)/(11-1) -> 0.02513067
D13: 0 | E13: 1 | F13: 2 | G13: 3 | H13: 4 | I13: 5 | J13: 6 | K13: 7 | L13: 8 | M13: 9 | N13: 10
C14: 2023 | D14: 2024 | E14: 2025 | F14: 2026 | G14: 2027 | H14: 2028 | I14: 2029 | J14: 2030 | K14: 2031 | L14: 2032 | M14: 2033 | N14: 2034
B15: g (Revenues) | D15: =+(D16-C16)/C16 -> 0.2713067 | E15: =+D15-$B$12 -> 0.24617603 | F15: =+E15-$B$12 -> 0.22104536 | G15: =+F15-$B$12 -> 0.19591469 | H15: =+G15-$B$12 -> 0.17078402 | I15: =+H15-$B$12 -> 0.14565335 | J15: =+I15-$B$12 -> 0.12052268 | K15: =+J15-$B$12 -> 0.095392011 | L15: =+K15-$B$12 -> 0.07026134 | ... N15: =+M15-$B$12 -> 0.02
B16: Revenues | C16: =+IS!C9 -> 247924063 | D16: =+IS!D9 -> 315187523 | E16: =+D16*D15+D16 -> 4.0070001e+08 | F16: =+E16*E15+E16 -> 4.9934275e+08 | G16: =+F16*F15+F16 -> 6.0972015e+08 | H16: =+G16*G15+G16 -> 7.2917328e+08 | I16: =+H16*H15+H16 -> 8.5370443e+08 | J16: =+I16*I15+I16 -> 9.7804934e+08 | K16: =+J16*J15+J16 -> 1.0959265e+09 | L16: =+K16*K15+K16 -> 1.2004691e+09 | ... N16: =+M16*M15+M16 -> 1.3428003e+09
B17: EBIT/Revenues | C17: =+C18/C16 -> 0.11910906 | D17: =+D18/D16 -> 0.11400948 | E17: =+$F$7 -> 0.11655927 | F17: =+$F$7 -> 0.11655927 | G17: =+$F$7 -> 0.11655927 | H17: =+$F$7 -> 0.11655927 | I17: =+$F$7 -> 0.11655927 | J17: =+$F$7 -> 0.11655927 | K17: =+$F$7 -> 0.11655927 | L17: =+$F$7 -> 0.11655927 | ... N17: =+$F$7 -> 0.11655927
B18: EBIT | C18: =+IS!C16 -> 29530003 | D18: =+IS!D16 -> 35934366 | E18: =+E16*E17 -> 46705302 | F18: =+F16*F17 -> 58203028 | G18: =+G16*G17 -> 71068537 | H18: =+H16*H17 -> 84991907 | I18: =+I16*I17 -> 99507167 | J18: =+J16*J17 -> 1.1400072e+08 | K18: =+K16*K17 -> 1.2774039e+08 | L18: =+L16*L17 -> 1.399258e+08 | ... N18: =+N16*N17 -> 1.5651582e+08
B19: Tau | C19: =+C5 -> 0.25 | D19: =+$C$19 -> 0.25 | E19: =+$C$19 -> 0.25 | F19: =+$C$19 -> 0.25 | G19: =+$C$19 -> 0.25 | H19: =+$C$19 -> 0.25 | I19: =+$C$19 -> 0.25 | J19: =+$C$19 -> 0.25 | K19: =+$C$19 -> 0.25 | ... N19: =+$C$19 -> 0.25
B20: NOPAT = EBIT * (1-Tau) | C20: =+C18*(1-C19) -> 22147502 | D20: =+D18*(1-D19) -> 26950774 | E20: =+E18*(1-E19) -> 35028976 | F20: =+F18*(1-F19) -> 43652271 | G20: =+G18*(1-G19) -> 53301403 | H20: =+H18*(1-H19) -> 63743931 | I20: =+I18*(1-I19) -> 74630375 | J20: =+J18*(1-J19) -> 85500540 | ... N20: =+N18*(1-N19) -> 1.1738687e+08
B21: OWK/Revenues | C21: =+C22/C16 -> 0.024779152 | D21: =+D22/D16 -> 0.076683978 | E21: =+$F$8 -> 0.060031565 | F21: =+$F$8 -> 0.060031565 | G21: =+$F$8 -> 0.060031565 | H21: =+$F$8 -> 0.060031565 | I21: =+$F$8 -> 0.060031565 | J21: =+$F$8 -> 0.060031565 | K21: =+$F$8 -> 0.060031565 | L21: =+$F$8 -> 0.060031565 | ... N21: =+$F$8 -> 0.060031565
B22: OWK | C22: =+'Análisis Financiero'!D6 -> 6143348 | D22: =+'Análisis Financiero'!E6 -> 24169833 | E22: =+E16*E21 -> 24054649 | F22: =+F16*F21 -> 29976327 | G22: =+G16*G21 -> 36602455 | H22: =+H16*H21 -> 43773413 | I22: =+I16*I21 -> 51249213 | J22: =+J16*J21 -> 58713832 | K22: =+K16*K21 -> 65790181 | L22: =+L16*L21 -> 72066038 | ... N22: =+N16*N21 -> 80610401
B23: PPE/Revenues | C23: =+C24/C16 -> 0.1768315 | D23: =+D24/D16 -> 0.1579517 | E23: =+$F$9 -> 0.1699916 | F23: =+$F$9 -> 0.1699916 | G23: =+$F$9 -> 0.1699916 | H23: =+$F$9 -> 0.1699916 | I23: =+$F$9 -> 0.1699916 | J23: =+$F$9 -> 0.1699916 | K23: =+$F$9 -> 0.1699916 | L23: =+$F$9 -> 0.1699916 | ... N23: =+$F$9 -> 0.1699916
B24: PPE | C24: =+'Análisis Financiero'!D41 -> 43840783 | D24: =+'Análisis Financiero'!E41 -> 49784405 | E24: =+E16*E23 -> 68115635 | F24: =+F16*F23 -> 84884072 | G24: =+G16*G23 -> 1.036473e+08 | H24: =+H16*H23 -> 1.2395333e+08 | I24: =+I16*I23 -> 1.4512258e+08 | J24: =+J16*J23 -> 1.6626017e+08 | K24: =+K16*K23 -> 1.8629829e+08 | L24: =+L16*L23 -> 2.0406966e+08 | ... N24: =+N16*N23 -> 2.2826476e+08
B25: IC | C25: =+'Análisis Financiero'!D47 -> 62676554 | D25: =+'Análisis Financiero'!E47 -> 81525292 | E25: =+E24+E22 -> 92170284 | F25: =+F24+F22 -> 1.148604e+08 | G25: =+G24+G22 -> 1.4024976e+08 | H25: =+H24+H22 -> 1.6772674e+08 | I25: =+I24+I22 -> 1.9637179e+08 | J25: =+J24+J22 -> 2.24974e+08 | K25: =+K24+K22 -> 2.5208847e+08 | L25: =+L24+L22 -> 2.761357e+08 | ... N25: =+N24+N22 -> 3.0887516e+08
B26: Cambio en IC | D26: =+D25-C25 -> 18848738 | E26: =+E25-D25 -> 10644992 | F26: =+F25-E25 -> 22690115 | G26: =+G25-F25 -> 25389358 | H26: =+H25-G25 -> 27476988 | I26: =+I25-H25 -> 28645048 | J26: =+J25-I25 -> 28602210 | K26: =+K25-J25 -> 27114470 | ... N26: =+N25-M25 -> 13337799
B27: CAPEX | D27: =+(D24-C24)+#REF! -> #REF! | E27: =+(E24-D24)+#REF! -> #REF! | F27: =+(F24-E24)+#REF! -> #REF! | G27: =+(G24-F24)+#REF! -> #REF! | H27: =+(H24-G24)+#REF! -> #REF! | I27: =+(I24-H24)+#REF! -> #REF! | J27: =+(J24-I24)+#REF! -> #REF! | K27: =+(K24-J24)+#REF! -> #REF! | ... N27: =+(N24-M24)+#REF! -> #REF!
B29: FCFF | E29: =+E20-E26 -> 24383985 | F29: =+F20-F26 -> 20962156 | G29: =+G20-G26 -> 27912044 | H29: =+H20-H26 -> 36266943 | I29: =+I20-I26 -> 45985327 | J29: =+J20-J26 -> 56898330 | K29: =+K20-K26 -> 68690824 | L29: =+L20-L26 -> 80897127 | ... N29: =+N20-N26 -> 1.0404907e+08
B30: FCF Descontado | E30: =+E29/(1+$C$3)^E13 -> 22080390 | F30: =+F29/(1+$C$3)^F13 -> 17188582 | G30: =+G29/(1+$C$3)^G13 -> 20725156 | H30: =+H29/(1+$C$3)^H13 -> 24384799 | I30: =+I29/(1+$C$3)^I13 -> 27998165 | J30: =+J29/(1+$C$3)^J13 -> 31369808 | K30: =+K29/(1+$C$3)^K13 -> 34293604 | L30: =+L29/(1+$C$3)^L13 -> 36572071 | ... N30: =+N29/(1+$C$3)^N13 -> 38570810
B31: Valor Terminal | C31: =+((1+C4)*N29)/(C3-C4) -> 1.258544e+09
B32: VT descontado | C32: =+C31/(1+C3)^N13 -> 4.6654009e+08
B33: EV | C33: =+SUM(E30:N30)+C32 -> 7.577608e+08
B34: Deuda neta | C34: =+'Análisis Financiero'!E34 -> 37254208
B35: MVE | C35: =+C33-C34 -> 7.205066e+08
B36: Precio por acción | C36: =+C35/Noticia!D4 -> 19.680595

Sheet DCF Base - Perpetuo
B1: DCF Base
B2: Supuestos generales
B3: k (WACC Meta) | C3: =+WACC!G44 -> 0.10432764
B4: g terminal | C4: 0.03
B5: Tau | C5: =+'Análisis Financiero'!C15 -> 0.25
B6: Supuestos operativos | C6: 2023 | D6: 2024 | E6: Promedio | F6: Se asume
B7: EBIT/Revenues | C7: =+C17 -> 0.11910906 | D7: =+D17 -> 0.11400948 | E7: =+AVERAGE(C7:D7) -> 0.11655927 | F7: =+E7 -> 0.11655927
B8: OWK/Revenues | C8: =+C21 -> 0.024779152 | D8: =+D21 -> 0.076683978 | E8: =+AVERAGE(C8:D8) -> 0.050731565 | F8: =+E8 -> 0.050731565
B9: PPE/Revenues | C9: =+C23 -> 0.1768315 | D9: =+D23 -> 0.1579517 | E9: =+AVERAGE(C9:D9) -> 0.1673916 | F9: =+E9 -> 0.1673916
B11: Tasa promedio de convergencia al crecimiento de largo plazo
B12: =+(D15-C4)/(11-1) -> 0.02413067
D13: 0 | E13: 1 | F13: 2 | G13: 3 | H13: 4 | I13: 5 | J13: 6 | K13: 7 | L13: 8 | M13: 9 | N13: 10
C14: 2023 | D14: 2024 | E14: 2025 | F14: 2026 | G14: 2027 | H14: 2028 | I14: 2029 | J14: 2030 | K14: 2031 | L14: 2032 | M14: 2033 | N14: 2034
B15: g (Revenues) | D15: =+(D16-C16)/C16 -> 0.2713067 | E15: =+D15-$B$12 -> 0.24717603 | F15: =+E15-$B$12 -> 0.22304536 | G15: =+F15-$B$12 -> 0.19891469 | H15: =+G15-$B$12 -> 0.17478402 | I15: =+H15-$B$12 -> 0.15065335 | J15: =+I15-$B$12 -> 0.12652268 | K15: =+J15-$B$12 -> 0.10239201 | L15: =+K15-$B$12 -> 0.07826134 | ... N15: =+M15-$B$12 -> 0.03
B16: Revenues | C16: =+IS!C9 -> 247924063 | D16: =+IS!D9 -> 315187523 | E16: =+D16*D15+D16 -> 4.0070001e+08 | F16: =+E16*E15+E16 -> 4.9974345e+08 | G16: =+F16*F15+F16 -> 6.1120891e+08 | H16: =+G16*G15+G16 -> 7.3278734e+08 | I16: =+H16*H15+H16 -> 8.6086686e+08 | J16: =+I16*I15+I16 -> 9.9055933e+08 | K16: =+J16*J15+J16 -> 1.1158876e+09 | L16: =+K16*K15+K16 -> 1.2301455e+09 | ... N16: =+M16*M15+M16 -> 1.3982183e+09
B17: EBIT/Revenues | C17: =+C18/C16 -> 0.11910906 | D17: =+D18/D16 -> 0.11400948 | E17: =+$F$7 -> 0.11655927 | F17: =+$F$7 -> 0.11655927 | G17: =+$F$7 -> 0.11655927 | H17: =+$F$7 -> 0.11655927 | I17: =+$F$7 -> 0.11655927 | J17: =+$F$7 -> 0.11655927 | K17: =+$F$7 -> 0.11655927 | L17: =+$F$7 -> 0.11655927 | ... N17: =+$F$7 -> 0.11655927
B18: EBIT | C18: =+IS!C16 -> 29530003 | D18: =+IS!D16 -> 35934366 | E18: =+E16*E17 -> 46705302 | F18: =+F16*F17 -> 58249733 | G18: =+G16*G17 -> 71242066 | H18: =+H16*H17 -> 85413159 | I18: =+I16*I17 -> 1.0034201e+08 | J18: =+J16*J17 -> 1.1545888e+08 | K18: =+K16*K17 -> 1.3006704e+08 | L18: =+L16*L17 -> 1.4338487e+08 | ... N18: =+N16*N17 -> 1.6297531e+08
B19: Tau | C19: =+C5 -> 0.25 | D19: =+$C$19 -> 0.25 | E19: =+$C$19 -> 0.25 | F19: =+$C$19 -> 0.25 | G19: =+$C$19 -> 0.25 | H19: =+$C$19 -> 0.25 | I19: =+$C$19 -> 0.25 | J19: =+$C$19 -> 0.25 | K19: =+$C$19 -> 0.25 | ... N19: =+$C$19 -> 0.25
B20: NOPAT = EBIT * (1-Tau) | C20: =+C18*(1-C19) -> 22147502 | D20: =+D18*(1-D19) -> 26950774 | E20: =+E18*(1-E19) -> 35028976 | F20: =+F18*(1-F19) -> 43687300 | G20: =+G18*(1-G19) -> 53431549 | H20: =+H18*(1-H19) -> 64059869 | I20: =+I18*(1-I19) -> 75256511 | J20: =+J18*(1-J19) -> 86594157 | ... N20: =+N18*(1-N19) -> 1.2223148e+08
B21: OWK/Revenues | C21: =+C22/C16 -> 0.024779152 | D21: =+D22/D16 -> 0.076683978 | E21: =+$F$8 -> 0.050731565 | F21: =+$F$8 -> 0.050731565 | G21: =+$F$8 -> 0.050731565 | H21: =+$F$8 -> 0.050731565 | I21: =+$F$8 -> 0.050731565 | J21: =+$F$8 -> 0.050731565 | K21: =+$F$8 -> 0.050731565 | L21: =+$F$8 -> 0.050731565 | ... N21: =+$F$8 -> 0.050731565
B22: OWK | C22: =+'Análisis Financiero'!D6 -> 6143348 | D22: =+'Análisis Financiero'!E6 -> 24169833 | E22: =+E16*E21 -> 20328139 | F22: =+F16*F21 -> 25352767 | G22: =+G16*G21 -> 31007584 | H22: =+H16*H21 -> 37175448 | I22: =+I16*I21 -> 43673123 | J22: =+J16*J21 -> 50252625 | K22: =+K16*K21 -> 56610722 | L22: =+L16*L21 -> 62407208 | ... N22: =+N16*N21 -> 70933801
B23: PPE/Revenues | C23: =+C24/C16 -> 0.1768315 | D23: =+D24/D16 -> 0.1579517 | E23: =+$F$9 -> 0.1673916 | F23: =+$F$9 -> 0.1673916 | G23: =+$F$9 -> 0.1673916 | H23: =+$F$9 -> 0.1673916 | I23: =+$F$9 -> 0.1673916 | J23: =+$F$9 -> 0.1673916 | K23: =+$F$9 -> 0.1673916 | L23: =+$F$9 -> 0.1673916 | ... N23: =+$F$9 -> 0.1673916
B24: PPE | C24: =+'Análisis Financiero'!D41 -> 43840783 | D24: =+'Análisis Financiero'!E41 -> 49784405 | E24: =+E16*E23 -> 67073815 | F24: =+F16*F23 -> 83652855 | G24: =+G16*G23 -> 1.0231124e+08 | H24: =+H16*H23 -> 1.2266244e+08 | I24: =+I16*I23 -> 1.4410188e+08 | J24: =+J16*J23 -> 1.6581131e+08 | K24: =+K16*K23 -> 1.867902e+08 | L24: =+L16*L23 -> 2.0591603e+08 | ... N24: =+N16*N23 -> 2.3404999e+08
B25: IC | C25: =+'Análisis Financiero'!D47 -> 62676554 | D25: =+'Análisis Financiero'!E47 -> 81525292 | E25: =+E24+E22 -> 87401954 | F25: =+F24+F22 -> 1.0900562e+08 | G25: =+G24+G22 -> 1.3331882e+08 | H25: =+H24+H22 -> 1.5983789e+08 | I25: =+I24+I22 -> 1.87775e+08 | J25: =+J24+J22 -> 2.1606393e+08 | K25: =+K24+K22 -> 2.4340092e+08 | L25: =+L24+L22 -> 2.6832323e+08 | ... N25: =+N24+N22 -> 3.0498379e+08
B26: Cambio en IC | D26: =+D25-C25 -> 18848738 | E26: =+E25-D25 -> 5876661.6 | F26: =+F25-E25 -> 21603668 | G26: =+G25-F25 -> 24313198 | H26: =+H25-G25 -> 26519072 | I26: =+I25-H25 -> 27937110 | J26: =+J25-I25 -> 28288933 | K26: =+K25-J25 -> 27336988 | ... N26: =+N25-M25 -> 15661225
B27: CAPEX | D27: =+(D24-C24)+#REF! -> #REF! | E27: =+(E24-D24)+#REF! -> #REF! | F27: =+(F24-E24)+#REF! -> #REF! | G27: =+(G24-F24)+#REF! -> #REF! | H27: =+(H24-G24)+#REF! -> #REF! | I27: =+(I24-H24)+#REF! -> #REF! | J27: =+(J24-I24)+#REF! -> #REF! | K27: =+(K24-J24)+#REF! -> #REF! | ... N27: =+(N24-M24)+#REF! -> #REF!
B29: FCFF | E29: =+E20-E26 -> 29152315 | F29: =+F20-F26 -> 22083632 | G29: =+G20-G26 -> 29118351 | H29: =+H20-H26 -> 37540797 | I29: =+I20-I26 -> 47319401 | J29: =+J20-J26 -> 58305223 | K29: =+K20-K26 -> 70213293 | L29: =+L20-L26 -> 82616341 | ... N29: =+N20-N26 -> 1.0657025e+08
